Workbook

Sheet 设计流程
A1: 阶段名称 | B1: 步骤名称 | C1: 核心执行任务 | D1: 输入数据 | E1: 输出数据 | F1: 关键技术要求/规范依据 | G1: 数据说明
A2: 第一阶段：原材料处理与基础性能测定 | B2: - | C2: 完成原材料取样、筛分、密度及沥青含量测试，获取基础参数 | D2: 新集料、RAP料样品 | E2: 集料级配曲线、RAP沥青含量、集料密度指标 | F2: 四分法取样规范；粗细集料密度测定方法区分 | G2: 试验数据按试件来源对应集料来源，按级配类型归类对应级配。
A3: - | B3: 1.1集料筛分与RAP沥青含量测定 | C3: 1. 新集料：四分法取样→水洗烘干→标准筛分→计算通过率； 2. RAP料：四分法取样→烘干→燃烧/离心抽提法测沥青含量→矿料水洗筛分→计算级配 | D3: 新集料各档位样品、RAP各档位样品 | E3: 新集料级配曲线、RAP沥青含量、RAP矿料级配曲线 | F3: 1. RAP按9.5mm关键筛孔分粗细档处理； 2. 严格记录水洗前后、筛分后质量数据
A4: - | B4: 1.2集料密度测定 | C4: 1. 粗集料（2.36/4.75mm）：水中重法测干燥、水中、表干状态质量→计算密度； 2. 细集料（<2.36mm）：容量瓶法测相关质量→计算密度 | D4: 粗细集料代表性样品 | E4: 集料表观相对密度、表干相对密度、毛体积密度 | F4: 粗细集料划分阈值遵循2.36mm或4.75mm标准
A5: 第二阶段：RA90#混合料配合比设计 | B5: - | C5: 确定RAP掺配比例，设计合成级配，验证体积指标并选定最佳沥青用量 | D5: 原材料基础性能数据 | E5: 3组合成级配方案、最佳沥青用量（OAC）、VV/VMA/VFA指标 | F5: 级配曲线无0.3-0.6mm驼峰
A6: - | B6: 2.1矿料合成级配设计 | C6: 1. 确定RAP掺配比例（30%/40%等），粗细RAP分开设计； 2. 设计3组粗细不同的合成级配（上/中/下限）； | D6: 新集料级配曲线、RAP矿料级配曲线 | E6: 3组合成级配方案 | F6: 合成级配曲线需平顺
A7: - | B7: 2.2最佳沥青用量与体积指标验证 | C7: 1. 按合成级配+预估沥青用量制备马歇尔试件； 2. 真空法测理论最大密度，表干法测毛体积密度； 3. 计算VV/VMA/VFA，绘制指标-沥青用量曲线→确定OAC | D7: 合成级配方案、预估沥青用量 | E7: 马歇尔试件、理论最大密度、毛体积密度、最佳沥青用量（OAC） | F7: 空隙率计算公式：VV=(1-毛体积密度/理论最大密度)×100% （3%<VV<6%，一般取4%）
A8: 第三阶段：RA90#混合料路用性能试验 | B8: - | C8: 完成马歇尔、水稳定性、高低温性能试验，验证混合料路用性能 | D8: 最佳配比混合料试件 | E8: 马歇尔稳定度(MS)/流值(FL)、冻融劈裂强度比(TSR)、动稳定度(DS)、弯拉性能指标 | F8: 各项试验温度、保温时长、加载速率遵循规范要求
A9: - | B9: 3.1马歇尔稳定度与流值试验 | C9: 1. 马歇尔试件60℃保温30-40min； 2. 50mm/min速率加载至破坏； 3. 记录稳定度与流值 | D9: 最佳配比马歇尔试件 | E9: 稳定度(MS)＞8kN 流值(FL)设计范围是 2.0 ~ 4.0 mm | F9: 试验温度60℃；加载速率50mm/min
A10: - | B10: 3.2水稳定性试验 | C10: 1. 冻融劈裂：试件饱水→-18℃冷冻16h→60℃水浴24h→25℃保温2h→劈裂试验→计算TSR； 2. 浸水马歇尔：试件60℃浸泡48h→测稳定度→计算残留稳定度比 | D10: 最佳配比马歇尔试件（两组） | E10: 冻融劈裂强度比(TSR)>75% 残留稳定度比>85% | F10: 冷冻温度-18℃；浸水时长48h
A11: - | B11: 3.3高温稳定性试验（车辙试验） | C11: 1. 轮碾法成型300×300×50mm板块试件； 2. 60℃保温大于4h，轮压0.7MPa； 3. 测试并计算动稳定度(DS) | D11: 最佳配比混合料 | E11: 车辙板试件 动稳定度(DS)>800次/mm | F11: 试件尺寸300×300×50mm；轮压0.7MPa
A12: - | B12: 3.4低温抗裂性试验（小梁弯曲） | C12: 1. 车辙板切割250×30×35mm小梁试件； 2. -10℃保温大于3h；3. 三点弯曲加载（50mm/min）→计算抗弯拉强度、最大弯拉应变 | D12: 车辙板试件 | E12: 小梁试件 抗弯拉强度 最大弯拉应变>2000με 弯曲劲度模量 | F12: 小梁尺寸250×30×35mm；试验温度-10℃

Sheet 集料筛分及密度
A1: 集料来源 | B1: 集料类型 | C1: 集料粒径/mm | D1: 筛分通过率/% | P1: 干重/g | Q1: 水中重/g | R1: 表干重/g | S1: 密度/(g/cm3) | V1: 试样烘干后质量 | W1: 水与瓶重 | X1: 饱和面干、水和瓶质量 | Y1: 饱和面干质量 | Z1: 密度/(g/cm3) | AC1: 抽提法 | AG1: 燃烧法 | AI1: 沥青用量/% | AJ1: 油石比/%
D2: 26.5 | E2: 19 | F2: 16 | G2: 13.2 | H2: 9.5 | I2: 4.75 | J2: 2.36 | K2: 1.18 | L2: 0.6 | M2: 0.3 | N2: 0.15 | O2: 0.075 | S2: 表观相对密度 | T2: 表干相对密度 | U2: 毛体积密度 | Z2: 表观相对密度 | AA2: 表干相对密度 | AB2: 毛体积密度 | AC2: 筒+纸 | AD2: 料重（抽提前） | AE2: 筒+纸+粉 | AF2: 料重（抽提后） | AG2: 燃烧前质量 | AH2: 燃烧后质量
A3: A | B3: 粗集料 | C3: 10-20 | D3: 100 | E3: 80.59709 | F3: 50.546914 | G3: 28.258906 | H3: 2.6894129 | I3: 0.48670346 | J3: 0 | K3: 0 | L3: 0 | M3: 0 | N3: 0 | O3: 0 | P3: 1989 | Q3: 1264.3 | R3: 2004.2 | S3: =P3/(P3-Q3) -> 2.744584 | T3: =R3/(R3-Q3) -> 2.7087444 | U3: =P3/(R3-Q3) -> 2.6882011 | AJ3: =(AD3+AC3-AE3-AF3)/(AE3+AF3-AC3) -> #DIV/0!
A4: A | B4: 粗集料 | C4: 5-10 | D4: 100 | E4: 100 | F4: 100 | G4: 100 | H4: 98.153117 | I4: 11.405753 | J4: 1.3477257 | K4: 0 | L4: 0 | M4: 0 | N4: 0 | O4: 0 | P4: 1964.8 | Q4: 1249 | R4: 1980.3 | S4: =P4/(P4-Q4) -> 2.7449008 | T4: =R4/(R4-Q4) -> 2.7079174 | U4: =P4/(R4-Q4) -> 2.6867223 | AJ4: =(AG2-AH2)/AH2 -> #VALUE!
A5: A | B5: 细集料 | C5: 0-5 | D5: 100 | E5: 100 | F5: 100 | G5: 100 | H5: 100 | I5: 99.363636 | J5: 62.96182 | K5: 43.563409 | L5: 26.855123 | M5: 14.573625 | N5: 7.8312868 | O5: 1.8948509 | V5: 296.9 | W5: 708.7 | X5: 902.3 | Y5: 300 | Z5: =V5/(V5+W5-X5) -> 2.874153 | AA5: =Y5/(Y5+W5-X5) -> 2.8195489 | AB5: =V5/(Y5+W5-X5) -> 2.7904135
A6: A | B6: 粗RAP料 | C6: 10-20 | D6: 100 | E6: 96.805854 | F6: 92.42359 | G6: 79.362893 | H6: 32.303056 | I6: 10.908308 | J6: 8.9367198 | K6: 7.4989238 | L6: 5.9750323 | M6: 4.2875592 | N6: 2.8755919 | O6: 1.5497202 | P6: 1032.5 | Q6: 659.6 | R6: 1042.2 | S6: =P6/(P6-Q6) -> 2.7688388 | T6: =R6/(R6-Q6) -> 2.7239937 | U6: =P6/(R6-Q6) -> 2.6986409 | AI6: 3.2882012 | AJ6: 3.4
A7: A | B7: 细RAP料 | C7: 0-10 | D7: 100 | E7: 100 | F7: 100 | G7: 100 | H7: 100 | I7: 63.157457 | J7: 40.687417 | K7: 31.066911 | L7: 24.275965 | M7: 17.684754 | N7: 11.825899 | O7: 8.9214381 | V7: 289.8 | W7: 708.5 | X7: 893.2 | Y7: 300.8 | Z7: =V7/(V7+W7-X7) -> 2.7573739 | AA7: =Y7/(Y7+W7-X7) -> 2.5908699 | AB7: =V7/(Y7+W7-X7) -> 2.496124 | AI7: =AJ7/(AJ7+100)*100 -> 3.8461538 | AJ7: 4
A8: B | B8: 粗集料 | C8: 10-20 | D8: 100 | E8: 93.712216 | F8: 66.512616 | G8: 33.717212 | H8: 5.6632526 | I8: 0.44716463 | J8: 0 | K8: 0 | L8: 0 | M8: 0 | N8: 0 | O8: 0 | P8: 1994 | Q8: 1262.05 | R8: 2001.1 | S8: 2.7242298 | T8: 2.7076652 | U8: 2.6980583
A9: B | B9: 粗集料 | C9: 5-10 | D9: 100 | E9: 100 | F9: 100 | G9: 100 | H9: 89.684047 | I9: 3.3944908 | J9: 1.1298305 | K9: 1.0423436 | L9: 0 | M9: 0 | N9: 0 | O9: 0 | P9: 1981.1 | Q9: 1252.05 | R9: 1995.4 | S9: 2.7173719 | T9: 2.6843344 | U9: 2.6650972
A10: B | B10: 粗集料 | C10: 3-5 | D10: 100 | E10: 100 | F10: 100 | G10: 100 | H10: 100 | I10: 95.985683 | J10: 12.69153 | K10: 5.8851935 | L10: 4.1839728 | M10: 3.6277139 | N10: 3.3515061 | O10: 3.1246478 | P10: 692.55 | Q10: 438.15 | R10: 698.85 | S10: 2.7222877 | T10: 2.6806674 | U10: 2.6565017
A11: B | B11: 细集料 | C11: 0-3 | D11: 100 | E11: 100 | F11: 100 | G11: 100 | H11: 100 | I11: 100 | J11: 69.772922 | K11: 41.231077 | L11: 19.951442 | M11: 11.610968 | N11: 9.3544702 | O11: 7.0408455 | V11: 294.3 | W11: 708.1 | X11: 895 | Y11: 300.5 | Z11: =V11/(V11+W11-X11) -> 2.7402235 | AA11: =Y11/(Y11+W11-X11) -> 2.6452465 | AB11: =V11/(Y11+W11-X11) -> 2.590669
A12: B | B12: 矿粉 | C12: / | D12: 100 | E12: 100 | F12: 100 | G12: 100 | H12: 100 | I12: 100 | J12: 100 | K12: 100 | L12: 100 | M12: 99.7 | N12: 97.1 | O12: 76.6
A13: B | B13: 粗RAP料 | C13: 7-14 | D13: 100 | E13: 100 | F13: 100 | G13: 92.75 | H13: 55.5 | I13: 23.1 | J13: 18.35 | K13: 13.95 | L13: 10.7 | M13: 8.6 | N13: 7.55 | O13: 6.25 | P13: 1027.85 | Q13: 649.5 | R13: 1033.05 | S13: 2.7166645 | T13: 2.6933907 | U13: 2.6798331 | AC13: 519.95 | AD13: 1300 | AE13: 594.05 | AF13: 1184.6 | AI13: 3.1784509 | AJ13: 3.2827929
A14: B | B14: 细RAP料 | C14: 0-7 | D14: 100 | E14: 100 | F14: 100 | G14: 100 | H14: 98.793898 | I14: 81.170722 | J14: 61.440213 | K14: 46.2292 | L14: 32.838359 | M14: 23.463475 | N14: 19.381251 | O14: 15.171029 | V14: 297.8 | W14: 721.8 | X14: 903.4 | Y14: 300 | Z14: =V14/(V14+W14-X14) -> 2.5628227 | AA14: =Y14/(Y14+W14-X14) -> 2.5337838 | AB14: =V14/(Y14+W14-X14) -> 2.5152027 | AC14: 520.2 | AD14: 1200 | AE14: 657.35 | AF14: 994.6 | AI14: =AJ14/(AJ14+100)*100 -> 5.6603774 | AJ14: 6
A15: C | B15: 粗集料 | C15: 10-20 | D15: 100 | E15: 93.712216 | F15: 66.512616 | G15: 33.717212 | H15: 5.6632526 | I15: 0.44716463 | J15: 0 | K15: 0 | L15: 0 | M15: 0 | N15: 0 | O15: 0 | P15: 1993.5 | Q15: 1261.3 | R15: 2001.4 | S15: =P15/(P15-Q15) -> 2.7226168 | T15: =R15/(R15-Q15) -> 2.7042292 | U15: =P15/(R15-Q15) -> 2.6935549
A16: C | B16: 粗集料 | C16: 5-10 | D16: 100 | E16: 100 | F16: 100 | G16: 100 | H16: 89.684047 | I16: 3.3944908 | J16: 1.1298305 | K16: 1.0423436 | L16: 0 | M16: 0 | N16: 0 | O16: 0 | P16: 1978.5 | Q16: 1250.7 | R16: 1994.7 | S16: =P16/(P16-Q16) -> 2.7184666 | T16: =R16/(R16-Q16) -> 2.6810484 | U16: =P16/(R16-Q16) -> 2.6592742
A17: C | B17: 粗集料 | C17: 10-15 | D17: 100 | E17: 100 | F17: 99.586446 | G17: 78.910673 | H17: 26.383191 | I17: 0.77822473 | J17: 0.43380263 | K17: 0.30670421 | L17: 0 | M17: 0 | N17: 0 | O17: 0 | P17: 995 | Q17: 616 | R17: 1002.8 | S17: =P17/(P17-Q17) -> 2.6253298 | T17: =R17/(R17-Q17) -> 2.5925543 | U17: =P17/(R17-Q17) -> 2.5723888
A18: C | B18: 粗集料 | C18: 3-5 | D18: 100 | E18: 100 | F18: 100 | G18: 100 | H18: 100 | I18: 95.985683 | J18: 12.69153 | K18: 5.8851935 | L18: 4.1839728 | M18: 3.6277139 | N18: 3.3515061 | O18: 3.1246478 | P18: 692.6 | Q18: 438.3 | R18: 698.8 | S18: =P18/(P18-Q18) -> 2.7235549 | T18: =R18/(R18-Q18) -> 2.6825336 | U18: =P18/(R18-Q18) -> 2.6587332
A19: C | B19: 细集料 | C19: 0-3 | D19: 100 | E19: 100 | F19: 100 | G19: 100 | H19: 100 | I19: 100 | J19: 69.772922 | K19: 41.231077 | L19: 19.951442 | M19: 11.610968 | N19: 9.3544702 | O19: 7.0408455 | V19: 294.3 | W19: 708.1 | X19: 895 | Y19: 300.5 | Z19: =V19/(V19+W19-X19) -> 2.7402235 | AA19: =Y19/(Y19+W19-X19) -> 2.6452465 | AB19: =V19/(Y19+W19-X19) -> 2.590669
A20: C | B20: 粗RAP料 | C20: 7-14 | D20: 100 | E20: 100 | F20: 100 | G20: 92.75 | H20: 55.5 | I20: 23.1 | J20: 18.35 | K20: 13.95 | L20: 10.7 | M20: 8.6 | N20: 7.55 | O20: 6.25 | P20: 1022.2 | Q20: 645.7 | R20: 1027.8 | S20: =P20/(P20-Q20) -> 2.7150066 | T20: =R20/(R20-Q20) -> 2.6898718 | U20: =P20/(R20-Q20) -> 2.6752159 | AC20: 519.95 | AD20: 1300 | AE20: 594.05 | AF20: 1184.6 | AI20: =100*AJ20/(100+AJ20) -> 3.1769231 | AJ20: =100*(AD20+AC20-AE20-AF20)/(AE20+AF20-AC20) -> 3.2811631
A21: C | B21: 细RAP料 | C21: 0-7 | D21: 100 | E21: 100 | F21: 100 | G21: 100 | H21: 98.793898 | I21: 81.170722 | J21: 61.440213 | K21: 46.2292 | L21: 32.838359 | M21: 23.463475 | N21: 19.381251 | O21: 15.171029 | V21: 297.8 | W21: 721.8 | X21: 903.4 | Y21: 300 | Z21: =V21/(V21+W21-X21) -> 2.5628227 | AA21: =Y21/(Y21+W21-X21) -> 2.5337838 | AB21: =V21/(Y21+W21-X21) -> 2.5152027 | AC21: 520.2 | AD21: 1200 | AE21: 657.35 | AF21: 994.6 | AI21: =100*AJ21/(100+AJ21) -> 5.6875 | AJ21: =100*(AD21+AC21-AE21-AF21)/(AE21+AF21-AC21) -> 6.0304838
A22: D | B22: 粗集料 | C22: 10-20 | D22: 100 | E22: 82.345575 | F22: 59.458728 | G22: 33.822964 | H22: 4.9826724 | I22: 0.71659447 | J22: 0 | K22: 0 | L22: 0 | M22: 0 | N22: 0 | O22: 0 | P22: 2061.5 | Q22: 1306.8 | R22: 2074.3 | S22: =P22/(P22-Q22) -> 2.731549 | T22: =R22/(R22-Q22) -> 2.702671 | U22: =P22/(R22-Q22) -> 2.6859935
A23: D | B23: 粗集料 | C23: 5-10 | D23: 100 | E23: 100 | F23: 99.5 | G23: 66.5 | H23: 6.5 | I23: 0 | J23: 0 | K23: 0 | L23: 0 | M23: 0 | N23: 0 | O23: 0 | P23: 2016.7 | Q23: 1313.9 | R23: 2026.7 | S23: =P23/(P23-Q23) -> 2.8695219 | T23: =R23/(R23-Q23) -> 2.8432941 | U23: =P23/(R23-Q23) -> 2.8292649
A24: D | B24: 粗集料 | C24: 3-5 | D24: 100 | E24: 100 | F24: 100 | G24: 100 | H24: 98.5 | I24: 25 | J24: 3 | K24: 2.5 | L24: 2 | M24: 2 | N24: 2 | O24: 2 | P24: 2031.3 | Q24: 1289.1 | R24: 2053 | S24: =P24/(P24-Q24) -> 2.7368634 | T24: =R24/(R24-Q24) -> 2.6875245 | U24: =P24/(R24-Q24) -> 2.6591177
A25: D | B25: 细集料 | C25: 0-3 | D25: 100 | E25: 100 | F25: 100 | G25: 100 | H25: 100 | I25: 99 | J25: 63.5 | K25: 45.5 | L25: 32 | M25: 22 | N25: 17 | O25: 12 | V25: 294.7 | W25: 708.9 | X25: 901.2 | Y25: 300 | Z25: =V25/(V25+W25-X25) -> 2.8779297 | AA25: =Y25/(Y25+W25-X25) -> 2.7855153 | AB25: =V25/(Y25+W25-X25) -> 2.7363045
A26: D | B26: 粗RAP料 | C26: 10-20 | D26: 100 | E26: =AVERAGE(E24,E25) -> 100 | F26: =AVERAGE(F24,F25) -> 100 | G26: =AVERAGE(G24,G25) -> 100 | H26: =AVERAGE(H24,H25) -> 99.25 | I26: =AVERAGE(I24,I25) -> 62 | J26: =AVERAGE(J24,J25) -> 33.25 | K26: =AVERAGE(K24,K25) -> 24 | L26: =AVERAGE(L24,L25) -> 17 | ... O26: =AVERAGE(O24,O25) -> 7 | P26: 1757.6 | Q26: 1113.7 | R26: 1766.9 | S26: =P26/(P26-Q26) -> 2.7296164 | T26: =R26/(R26-Q26) -> 2.7049908 | U26: =P26/(R26-Q26) -> 2.6907532 | AC26: 519.35 | AD26: 1200 | AE26: 568.05 | AF26: 1117.15 | AI26: =100*AJ26/(100+AJ26) -> 2.8458333 | AJ26: =100*(AD26+AC26-AE26-AF26)/(AE26+AF26-AC26) -> 2.9291933
A27: D | B27: 细RAP料 | C27: 0-10 | D27: 100 | E27: =AVERAGE(E25,E26) -> 100 | F27: =AVERAGE(F25,F26) -> 100 | G27: =AVERAGE(G25,G26) -> 100 | H27: =AVERAGE(H25,H26) -> 99.625 | I27: =AVERAGE(I25,I26) -> 80.5 | J27: =AVERAGE(J25,J26) -> 48.375 | K27: =AVERAGE(K25,K26) -> 34.75 | L27: =AVERAGE(L25,L26) -> 24.5 | ... O27: =AVERAGE(O25,O26) -> 9.5 | V27: 291.8 | W27: 708.7 | X27: 892.4 | Y27: 300 | Z27: =V27/(V27+W27-X27) -> 2.6993525 | AA27: =Y27/(Y27+W27-X27) -> 2.5795357 | AB27: =V27/(Y27+W27-X27) -> 2.5090284 | AC27: 519.5 | AD27: 1198.5 | AE27: 618.35 | AF27: 1043.75 | AI27: =100*AJ27/(100+AJ27) -> 4.6641635 | AJ27: =100*(AD27+AC27-AE27-AF27)/(AE27+AF27-AC27) -> 4.8923508
A28: E | B28: 粗集料 | C28: 10-20 | D28: 100 | E28: 93.712216 | F28: 66.512616 | G28: 33.717212 | H28: 5.6632526 | I28: 0.44716463 | J28: 0 | K28: 0 | L28: 0 | M28: 0 | N28: 0 | O28: 0 | P28: 1993.5 | Q28: 1261.3 | R28: 2001.4 | S28: =P28/(P28-Q28) -> 2.7226168 | T28: =R28/(R28-Q28) -> 2.7042292 | U28: =P28/(R28-Q28) -> 2.6935549
A29: E | B29: 粗集料 | C29: 5-10 | D29: 100 | E29: 100 | F29: 100 | G29: 100 | H29: 89.684047 | I29: 3.3944908 | J29: 1.1298305 | K29: 1.0423436 | L29: 0 | M29: 0 | N29: 0 | O29: 0 | P29: 1978.5 | Q29: 1250.7 | R29: 1994.7 | S29: =P29/(P29-Q29) -> 2.7184666 | T29: =R29/(R29-Q29) -> 2.6810484 | U29: =P29/(R29-Q29) -> 2.6592742
A30: E | B30: 粗集料 | C30: 10-15 | D30: 100 | E30: 100 | F30: 99.586446 | G30: 78.910673 | H30: 26.383191 | I30: 0.77822473 | J30: 0.43380263 | K30: 0.30670421 | L30: 0 | M30: 0 | N30: 0 | O30: 0 | P30: 995 | Q30: 616 | R30: 1002.8 | S30: =P30/(P30-Q30) -> 2.6253298 | T30: =R30/(R30-Q30) -> 2.5925543 | U30: =P30/(R30-Q30) -> 2.5723888
A31: E | B31: 粗集料 | C31: 3-5 | D31: 100 | E31: 100 | F31: 100 | G31: 100 | H31: 100 | I31: 95.985683 | J31: 12.69153 | K31: 5.8851935 | L31: 4.1839728 | M31: 3.6277139 | N31: 3.3515061 | O31: 3.1246478 | P31: 692.6 | Q31: 438.3 | R31: 698.8 | S31: =P31/(P31-Q31) -> 2.7235549 | T31: =R31/(R31-Q31) -> 2.6825336 | U31: =P31/(R31-Q31) -> 2.6587332
A32: E | B32: 细集料 | C32: 0-3 | D32: 100 | E32: 100 | F32: 100 | G32: 100 | H32: 100 | I32: 100 | J32: 69.772922 | K32: 41.231077 | L32: 19.951442 | M32: 11.610968 | N32: 9.3544702 | O32: 7.0408455 | V32: 294.3 | W32: 708.1 | X32: 895 | Y32: 300.5 | Z32: =V32/(V32+W32-X32) -> 2.7402235 | AA32: =Y32/(Y32+W32-X32) -> 2.6452465 | AB32: =V32/(Y32+W32-X32) -> 2.590669
A33: E | B33: 矿粉 | C33: / | D33: 100 | E33: 100 | F33: 100 | G33: 100 | H33: 100 | I33: 100 | J33: 100 | K33: 100 | L33: 100 | M33: 99.7 | N33: 97.1 | O33: 76.6 | V33: 295.3 | W33: 722 | X33: 909.1 | Y33: 301 | Z33: =V33/(V33+W33-X33) -> 2.7292052 | AA33: =Y33/(Y33+W33-X33) -> 2.642669 | AB33: =V33/(Y33+W33-X33) -> 2.5926251
A34: F | B34: 粗集料 | C34: >22 | D34: 100 | E34: 14.7525 | F34: 3.64 | G34: 0.1275 | H34: 0 | I34: 0 | J34: 0 | K34: 0 | L34: 0 | M34: 0 | N34: 0 | O34: 0 | P34: 1430.1 | Q34: 906 | R34: 1434.9 | S34: =P34/(P34-Q34) -> 2.7286777 | T34: =R34/(R34-Q34) -> 2.7129892 | U34: =P34/(R34-Q34) -> 2.7039138
A35: F | B35: 粗集料 | C35: 16-22 | D35: 100 | E35: 99.47 | F35: 94.023333 | G35: 16.586667 | H35: 0.45 | I35: 0.27333333 | J35: 0 | K35: 0 | L35: 0 | M35: 0 | N35: 0 | O35: 0 | P35: 1601.4 | Q35: 1013.6 | R35: 1609.4 | S35: =P35/(P35-Q35) -> 2.7243961 | T35: =R35/(R35-Q35) -> 2.701242 | U35: =P35/(R35-Q35) -> 2.6878147
A36: F | B36: 粗集料 | C36: 11-16 | D36: 100 | E36: 100 | F36: 100 | G36: 97.423333 | H36: 44.356667 | I36: 0.28333333 | J36: 0.19333333 | K36: 0.10333333 | L36: 0 | M36: 0 | N36: 0 | O36: 0 | P36: 1344.9 | Q36: 851.2 | R36: 1351.3 | S36: =P36/(P36-Q36) -> 2.724124 | T36: =R36/(R36-Q36) -> 2.7020596 | U36: =P36/(R36-Q36) -> 2.6892621
A37: F | B37: 粗集料 | C37: 7-11 | D37: 100 | E37: 100 | F37: 100 | G37: 100 | H37: 96.67 | I37: 3.0533333 | J37: 0.63 | K37: 0 | L37: 0 | M37: 0 | N37: 0 | O37: 0 | P37: 1486.6 | Q37: 940.3 | R37: 1494.8 | S37: =P37/(P37-Q37) -> 2.7212154 | T37: =R37/(R37-Q37) -> 2.6957619 | U37: =P37/(R37-Q37) -> 2.6809739
A38: F | B38: 粗集料 | C38: 4-7 | D38: 100 | E38: 100 | F38: 100 | G38: 100 | H38: 100 | I38: 70.359936 | J38: 8.4791667 | K38: 4.5041667 | L38: 2.5666667 | M38: 1.8375 | N38: 1.5875 | O38: 1.4208333 | P38: 941.2 | Q38: 595.4 | R38: 950.5 | S38: =P38/(P38-Q38) -> 2.7218045 | T38: =R38/(R38-Q38) -> 2.6767108 | U38: =P38/(R38-Q38) -> 2.650521
A39: F | B39: 细集料 | C39: 0-4 | D39: 100 | E39: 100 | F39: 100 | G39: 100 | H39: 100 | I39: 100 | J39: 81.365 | K39: 59.195 | L39: 34.705 | M39: 19.21 | N39: 13.9 | O39: 11.54 | V39: 295.3 | W39: 722 | X39: 909.1 | Y39: 301 | Z39: =V39/(V39+W39-X39) -> 2.7292052 | AA39: =Y39/(Y39+W39-X39) -> 2.642669 | AB39: =V39/(Y39+W39-X39) -> 2.5926251
A40: F | B40: 矿粉 | C40: \ | D40: 100 | E40: 100 | F40: 100 | G40: 100 | H40: 100 | I40: 100 | J40: 100 | K40: 100 | L40: 100 | M40: 99.6875 | N40: 97.1125 | O40: 76.6125
...

Sheet 级配
A1: 集料来源 | B1: 级配类型 | C1: 集料类型 | D1: 集料粒径/mm | E1: 新旧料比例 | F1: 各档比例 | G1: 筛孔尺寸/mm | S1: 表观相对密度 | T1: 毛体积相对密度 | W1: 矿料的合成表观相对密度 | X1: 合成矿料的吸水率wx | Y1: 合成矿料的沥青吸收系数C | Z1: 合成矿料的有效相对密度rse | AA1: 沥青混合料最大理论相对密度rti | AB1: 矿料的合成毛体积相对密度 | AC1: 油石比Pai（%） | AD1: 沥青用量 | AE1: RAP油石比Pri（%） | AF1: 新加沥青油石比Pri（%）
G2: 26.5 | H2: 19 | I2: 16 | J2: 13.2 | K2: 9.5 | L2: 4.75 | M2: 2.36 | N2: 1.18 | O2: 0.6 | P2: 0.3 | Q2: 0.15 | R2: 0.075 | AG2: 密级配沥青混凝土混合料矿料级配范围
A3: A | B3: 90# AC-20-1 | C3: 粗集料 | D3: 10-20 | E3: 0.5 | F3: 0.6 | G3: 100 | H3: 80.59709 | I3: 50.546914 | J3: 28.258906 | K3: 2.6894129 | L3: 0.48670346 | M3: 0 | N3: 0 | O3: 0 | P3: 0 | Q3: 0 | R3: 0 | S3: 2.745 | T3: 2.688 | U3: =级配!F3/S3*E3 -> 0.10928962 | V3: =级配!F3/T3*E3 -> 0.11160714 | W3: =1/SUM(U3:U11) -> 2.7740065 | X3: 0.423 | Y3: =0.033*X3*X3-0.2936*X3+0.9336 -> 0.81531186 | Z3: =Y3*W3+(1-Y3)*AB3 -> 2.7560115 | AA3: 2.5721137 | AB3: =1/SUM(V3:V11) -> 2.676572 | AC3: 4.3 | AD3: =100*AC3/(100+AC3) -> 4.1227229 | AF3: =AC3-E10*F10*AE10-E10*F11*AE11 -> 2.48 | AG3: 级配类型 | AI3: 通过下列筛孔(mm)的质量百分率（%)
C4: 粗集料 | D4: 5-10 | F4: 0.1 | G4: 100 | H4: 100 | I4: 100 | J4: 100 | K4: 80.59709 | L4: 50.546914 | M4: 28.258906 | N4: 2.6894129 | O4: 0.48670346 | P4: 0 | Q4: 0 | R4: 0 | S4: 2.745 | T4: 2.687 | U4: =级配!F4/S4*E3 -> 0.018214936 | V4: =级配!F4/T4*E3 -> 0.018608113 | AI4: 31.5 | AJ4: 26.5 | AK4: 19 | AL4: 16 | AM4: 13.2 | AN4: 9.5 | AO4: 4.75 | AP4: 2.36 | AQ4: 1.18 | AR4: 0.6 | AS4: 0.3 | AT4: 0.15 | AU4: 0.075
C5: 细集料 | D5: 0-5 | F5: 0.3 | G5: 100 | H5: 100 | I5: 100 | J5: 100 | K5: 100 | L5: 99.363636 | M5: 62.96182 | N5: 43.563409 | O5: 26.855123 | P5: 14.573625 | Q5: 7.8312868 | R5: 1.8948509 | S5: 2.874 | T5: 2.79 | U5: =级配!F5/S5*E3 -> 0.052192067 | V5: =级配!F5/T5*E3 -> 0.053763441 | AG5: 粗粒式 | AH5: AC- 25 | AI5: 100 | AJ5: 90~100 | AK5: 75~90 | AL5: 65-83 | AM5: 57～76 | AN5: 45 ～65 | AO5: 24～52 | AP5: 16～42 | AQ5: 12～33 | AR5: 8~24 | AS5: 5~17 | AT5: 4~13 | AU5: 3~7
C6: 矿粉 | D6: 矿粉 | F6: 0 | G6: 100 | H6: 100 | I6: 100 | J6: 100 | K6: 89.684047 | L6: 3.3944908 | M6: 1.1298305 | N6: 1.0423436 | O6: 0 | P6: 0 | Q6: 0 | R6: 0 | S6: 2.7222877 | T6: 2.6806674 | U6: =级配!F6/S6*E3 -> 0 | V6: =级配!F6/T6*E3 -> 0 | AG6: 中粒式 | AH6: AC-20 | AJ6: 100 | AK6: 90~100 | AL6: 78～92 | AM6: 62~80 | AN6: 50~72 | AO6: 26~56 | AP6: 16～44 | AQ6: 12~33 | AR6: 8～24 | AS6: 5～~17 | AT6: 4~13 | AU6: 3～7
C7: 矿粉 | D7: 矿粉 | F7: 0 | G7: 100 | H7: 100 | I7: 100 | J7: 100 | K7: 100 | L7: 95.985683 | M7: 12.69153 | N7: 5.8851935 | O7: 4.1839728 | P7: 3.6277139 | Q7: 3.3515061 | R7: 3.1246478 | S7: 2.7173719 | T7: 2.6843344 | U7: =级配!F7/S7*E3 -> 0 | V7: =级配!F7/T7*E3 -> 0 | AH7: AC- 16 | AK7: 100 | AL7: 90~100 | AM7: 76~92 | AN7: 60~80 | AO7: 34～62 | AP7: 20～48 | AQ7: 13~36 | AR7: 9～26 | AS7: 7~18 | AT7: 5-14 | AU7: 4~8
C8: 矿粉 | D8: 矿粉 | F8: 0 | G8: 100 | H8: 100 | I8: 100 | J8: 100 | K8: 100 | L8: 100 | M8: 69.772922 | N8: 41.231077 | O8: 19.951442 | P8: 11.610968 | Q8: 9.3544702 | R8: 7.0408455 | S8: 2.7173719 | T8: 2.6843344 | U8: =级配!F8/S8*E3 -> 0 | V8: =级配!F8/T8*E3 -> 0 | AG8: 细粒式 | AH8: AC-13 | AL8: 100 | AM8: 90~100 | AN8: 68 ～85 | AO8: 38～68 | AP8: 24 ~50 | AQ8: 15～38 | AR8: 10~28 | AS8: 7~20 | AT8: 5~15 | AU8: 4~8
C9: 矿粉 | D9: 矿粉 | F9: 0 | G9: 100 | H9: 100 | I9: 100 | J9: 100 | K9: 100 | L9: 100 | M9: 100 | N9: 100 | O9: 100 | P9: 100 | Q9: 100 | R9: 100 | S9: 2.7173719 | T9: 2.6843344 | U9: =级配!F9/S9*E3 -> 0 | V9: =级配!F9/T9*E3 -> 0 | AH9: AC-10 | AM9: 100 | AN9: 90~100 | AO9: 45 ～75 | AP9: 30 ～58 | AQ9: 20~44 | AR9: 13～32 | AS9: 9~23 | AT9: 6～ 16 | AU9: 4~8
C10: 粗RAP料 | D10: 10-20 | E10: 0.5 | F10: 0.6 | G10: 100 | H10: 96.805854 | I10: 92.42359 | J10: 79.362893 | K10: 32.303056 | L10: 10.908308 | M10: 8.9367198 | N10: 7.4989238 | O10: 5.9750323 | P10: 4.2875592 | Q10: 2.8755919 | R10: 1.5497202 | S10: 2.768 | T10: 2.678 | U10: =级配!F10/S10*E10 -> 0.1083815 | V10: =级配!F10/T10*E10 -> 0.1120239 | AE10: 3.4 | AG10: 砂粒式 | AH10: AC-5 | AN10: 100 | AO10: 90~100 | AP10: 55~ 75 | AQ10: 35 ～55 | AR10: 20~40 | AS10: 12~28 | AT10: 7～18 | AU10: 5~10
C11: 细RAP料 | D11: 0-10 | F11: 0.4 | G11: 100 | H11: 100 | I11: 100 | J11: 100 | K11: 84.391023 | L11: 25.308901 | M11: 9.4813819 | N11: 5.7073212 | O11: 4.4717156 | P11: 3.5723292 | Q11: 2.799025 | R11: 2.1433975 | S11: 2.762 | T11: 2.577 | U11: =级配!F11/S11*E10 -> 0.072411296 | V11: =级配!F11/T11*E10 -> 0.077609624 | AE11: 4
F12: 级配1 | G12: =$E$29*($F$29*G3+$F$30*G4+$F$31*G5+$F$32*G6+$F$33*G7+$F$34*G8+$F$35*G9)+$E$36*($F$36*G10+$F$37*G11) -> 100 | H12: =E3*(F3*H3+F4*H4+F5*H5+F6*H6+F7*H7+F8*H8+F9*H9)+E10*(F10*H10+F11*H11) -> 93.220883 | I12: =E3*(F3*I3+F4*I4+F5*I5+F6*I6+F7*I7+F8*I8+F9*I9)+E10*(F10*I10+F11*I11) -> 82.891151 | J12: =E3*(F3*J3+F4*J4+F5*J5+F6*J6+F7*J7+F8*J8+F9*J9)+E10*(F10*J10+F11*J11) -> 72.28654 | K12: =E3*(F3*K3+F4*K4+F5*K5+F6*K6+F7*K7+F8*K8+F9*K9)+E10*(F10*K10+F11*K11) -> 46.4058 | L12: =E3*(F3*L3+F4*L4+F5*L5+F6*L6+F7*L7+F8*L8+F9*L9)+E10*(F10*L10+F11*L11) -> 25.912175 | M12: =E3*(F3*M3+F4*M4+F5*M5+F6*M6+F7*M7+F8*M8+F9*M9)+E10*(F10*M10+F11*M11) -> 15.434511 | N12: =E3*(F3*N3+F4*N4+F5*N5+F6*N6+F7*N7+F8*N8+F9*N9)+E10*(F10*N10+F11*N11) -> 10.060123 | O12: =E3*(F3*O3+F4*O4+F5*O5+F6*O6+F7*O7+F8*O8+F9*O9)+E10*(F10*O10+F11*O11) -> 6.7394565 | P12: =E3*(F3*P3+F4*P4+F5*P5+F6*P6+F7*P7+F8*P8+F9*P9)+E10*(F10*P10+F11*P11) -> 4.1867773 | Q12: =E3*(F3*Q3+F4*Q4+F5*Q5+F6*Q6+F7*Q7+F8*Q8+F9*Q9)+E10*(F10*Q10+F11*Q11) -> 2.5971756 | R12: =E3*(F3*R3+F4*R4+F5*R5+F6*R6+F7*R7+F8*R8+F9*R9)+E10*(F10*R10+F11*R11) -> 1.1778232
F13: 级配上限 | G13: 100 | H13: 100 | I13: 92 | J13: 80 | K13: 72 | L13: 56 | M13: 44 | N13: 33 | O13: 24 | P13: 17 | Q13: 13 | R13: 7
F14: 级配中值 | G14: =(G13+G15)/2 -> 100 | H14: =(H13+H15)/2 -> 95 | I14: =(I13+I15)/2 -> 85 | J14: =(J13+J15)/2 -> 71 | K14: =(K13+K15)/2 -> 61 | L14: =(L13+L15)/2 -> 41 | M14: =(M13+M15)/2 -> 30 | N14: =(N13+N15)/2 -> 22.5 | ... R14: =(R13+R15)/2 -> 5
F15: 级配下限 | G15: 100 | H15: 90 | I15: 78 | J15: 62 | K15: 50 | L15: 26 | M15: 16 | N15: 12 | O15: 8 | P15: 5 | Q15: 4 | R15: 3
A16: A | B16: 90# AC-20-2 | C16: 粗集料 | D16: 10-20 | E16: 0.5 | F16: 0.4 | G16: 100 | H16: 80.59709 | I16: 50.546914 | J16: 28.258906 | K16: 2.6894129 | L16: 0.48670346 | M16: 0 | N16: 0 | O16: 0 | P16: 0 | Q16: 0 | R16: 0 | S16: 2.745 | T16: 2.688 | U16: =级配!F16/S16*E16 -> 0.072859745 | V16: =级配!F16/T16*E16 -> 0.074404762 | W16: =1/SUM(U16:U24) -> 2.7855137 | X16: 0.423 | Y16: =0.033*X16*X16-0.2936*X16+0.9336 -> 0.81531186 | Z16: =Y16*W16+(1-Y16)*AB16 -> 2.768152 | AA16: 2.5721137 | AB16: =1/SUM(V16:V24) -> 2.6915085 | AC16: 4.3 | AD16: =100*AC16/(100+AC16) -> 4.1227229 | AF16: =AC16-E23*F23*AE23-E23*F24*AE24 -> 2.51
C17: 粗集料 | D17: 5-10 | F17: 0 | G17: 100 | H17: 100 | I17: 100 | J17: 100 | K17: 80.59709 | L17: 50.546914 | M17: 28.258906 | N17: 2.6894129 | O17: 0.48670346 | P17: 0 | Q17: 0 | R17: 0 | S17: 2.745 | T17: 2.687 | U17: =级配!F17/S17*E16 -> 0 | V17: =级配!F17/T17*E16 -> 0
C18: 细集料 | D18: 0-5 | F18: 0.5 | G18: 100 | H18: 100 | I18: 100 | J18: 100 | K18: 100 | L18: 99.363636 | M18: 62.96182 | N18: 43.563409 | O18: 26.855123 | P18: 14.573625 | Q18: 7.8312868 | R18: 1.8948509 | S18: 2.874 | T18: 2.79 | U18: =级配!F18/S18*E16 -> 0.086986778 | V18: =级配!F18/T18*E16 -> 0.089605735
C19: 矿粉 | D19: 矿粉 | F19: 0 | G19: 100 | H19: 100 | I19: 100 | J19: 100 | K19: 89.684047 | L19: 3.3944908 | M19: 1.1298305 | N19: 1.0423436 | O19: 0 | P19: 0 | Q19: 0 | R19: 0 | S19: 2.7222877 | T19: 2.6806674 | U19: =级配!F19/S19*E16 -> 0 | V19: =级配!F19/T19*E16 -> 0
C20: 矿粉 | D20: 矿粉 | F20: 0 | G20: 100 | H20: 100 | I20: 100 | J20: 100 | K20: 100 | L20: 95.985683 | M20: 12.69153 | N20: 5.8851935 | O20: 4.1839728 | P20: 3.6277139 | Q20: 3.3515061 | R20: 3.1246478 | S20: 2.7173719 | T20: 2.6843344 | U20: =级配!F20/S20*E16 -> 0 | V20: =级配!F20/T20*E16 -> 0
C21: 矿粉 | D21: 矿粉 | F21: 0 | G21: 100 | H21: 100 | I21: 100 | J21: 100 | K21: 100 | L21: 100 | M21: 69.772922 | N21: 41.231077 | O21: 19.951442 | P21: 11.610968 | Q21: 9.3544702 | R21: 7.0408455 | S21: 2.7173719 | T21: 2.6843344 | U21: =级配!F21/S21*E16 -> 0 | V21: =级配!F21/T21*E16 -> 0
C22: 矿粉 | D22: 矿粉 | F22: 0.1 | G22: 100 | H22: 100 | I22: 100 | J22: 100 | K22: 100 | L22: 100 | M22: 100 | N22: 100 | O22: 100 | P22: 100 | Q22: 100 | R22: 100 | S22: 2.7173719 | T22: 2.6843344 | U22: =级配!F22/S22*E16 -> 0.018400131 | V22: =级配!F22/T22*E16 -> 0.018626591
C23: 粗RAP料 | D23: 10-20 | E23: 0.5 | F23: 0.7 | G23: 100 | H23: 96.805854 | I23: 92.42359 | J23: 79.362893 | K23: 32.303056 | L23: 10.908308 | M23: 8.9367198 | N23: 7.4989238 | O23: 5.9750323 | P23: 4.2875592 | Q23: 2.8755919 | R23: 1.5497202 | S23: 2.768 | T23: 2.678 | U23: =级配!F23/S23*E23 -> 0.12644509 | V23: =级配!F23/T23*E23 -> 0.13069455 | AE23: 3.4
C24: 细RAP料 | D24: 0-10 | F24: 0.3 | G24: 100 | H24: 100 | I24: 100 | J24: 100 | K24: 84.391023 | L24: 25.308901 | M24: 9.4813819 | N24: 5.7073212 | O24: 4.4717156 | P24: 3.5723292 | Q24: 2.799025 | R24: 2.1433975 | S24: 2.762 | T24: 2.577 | U24: =级配!F24/S24*E23 -> 0.054308472 | V24: =级配!F24/T24*E23 -> 0.058207218 | AE24: 4
F25: 级配1 | G25: =$E$29*($F$29*G16+$F$30*G17+$F$31*G18+$F$32*G19+$F$33*G20+$F$34*G21+$F$35*G22)+$E$36*($F$36*G23+$F$37*G24) -> 100 | H25: =E16*(F16*H16+F17*H17+F18*H18+F19*H19+F20*H20+F21*H21+F22*H22)+E23*(F23*H23+F24*H24) -> 95.001467 | I25: =E16*(F16*I16+F17*I17+F18*I18+F19*I19+F20*I20+F21*I21+F22*I22)+E23*(F23*I23+F24*I24) -> 87.457639 | J25: =E16*(F16*J16+F17*J17+F18*J18+F19*J19+F20*J20+F21*J21+F22*J22)+E23*(F23*J23+F24*J24) -> 78.428794 | K25: =E16*(F16*K16+F17*K17+F18*K18+F19*K19+F20*K20+F21*K21+F22*K22)+E23*(F23*K23+F24*K24) -> 54.502606 | L25: =E16*(F16*L16+F17*L17+F18*L18+F19*L19+F20*L20+F21*L21+F22*L22)+E23*(F23*L23+F24*L24) -> 37.552493 | M25: =E16*(F16*M16+F17*M17+F18*M18+F19*M19+F20*M20+F21*M21+F22*M22)+E23*(F23*M23+F24*M24) -> 25.290514 | N25: =E16*(F16*N16+F17*N17+F18*N18+F19*N19+F20*N20+F21*N21+F22*N22)+E23*(F23*N23+F24*N24) -> 19.371574 | O25: =E16*(F16*O16+F17*O17+F18*O18+F19*O19+F20*O20+F21*O21+F22*O22)+E23*(F23*O23+F24*O24) -> 14.475799 | P25: =E16*(F16*P16+F17*P17+F18*P18+F19*P19+F20*P20+F21*P21+F22*P22)+E23*(F23*P23+F24*P24) -> 10.679901 | Q25: =E16*(F16*Q16+F17*Q17+F18*Q18+F19*Q19+F20*Q20+F21*Q21+F22*Q22)+E23*(F23*Q23+F24*Q24) -> 8.3841326 | R25: =E16*(F16*R16+F17*R17+F18*R18+F19*R19+F20*R20+F21*R21+F22*R22)+E23*(F23*R23+F24*R24) -> 6.3376244
F26: 级配上限 | G26: 100 | H26: 100 | I26: 92 | J26: 80 | K26: 72 | L26: 56 | M26: 44 | N26: 33 | O26: 24 | P26: 17 | Q26: 13 | R26: 7
F27: 级配中值 | G27: =(G26+G28)/2 -> 100 | H27: =(H26+H28)/2 -> 95 | I27: =(I26+I28)/2 -> 85 | J27: =(J26+J28)/2 -> 71 | K27: =(K26+K28)/2 -> 61 | L27: =(L26+L28)/2 -> 41 | M27: =(M26+M28)/2 -> 30 | N27: =(N26+N28)/2 -> 22.5 | ... R27: =(R26+R28)/2 -> 5
F28: 级配下限 | G28: 100 | H28: 90 | I28: 78 | J28: 62 | K28: 50 | L28: 26 | M28: 16 | N28: 12 | O28: 8 | P28: 5 | Q28: 4 | R28: 3
A29: B | B29: AC-20 | C29: 粗集料 | D29: 20-30 | E29: 0.5 | F29: 0.18 | G29: 99.6 | H29: 14.7 | I29: 0 | J29: 0 | K29: 0 | L29: 0 | M29: 0 | N29: 0 | O29: 0 | P29: 0 | Q29: 0 | R29: 0 | S29: =[1]集料筛分及密度!S8 -> 2.7242298 | T29: =[1]集料筛分及密度!T8 -> 2.7076652 | U29: =级配!F29/S29*E29 -> 0.033036861 | V29: =级配!F29/T29*E29 -> 0.033238969 | W29: =1/SUM(U29:U37) -> 2.6875608 | X29: 0.708 | Y29: 0.742 | Z29: =Y29*W29+(1-Y29)*AB29 -> 2.6789255 | AA29: 2.544 | AB29: =1/SUM(V29:V37) -> 2.6540905 | AC29: 4.2 | AD29: 4.03 | AF29: =AC29-E36*F36*AE36-E36*F37*AE37 -> 2.0151621
C30: 粗集料 | D30: 10-20 | F30: 0.28 | G30: 100 | H30: 93.712216 | I30: 66.512616 | J30: 33.717212 | K30: 5.6632526 | L30: 0.44716463 | M30: 0 | N30: 0 | O30: 0 | P30: 0 | Q30: 0 | R30: 0 | S30: =[1]集料筛分及密度!S9 -> 2.7173719 | T30: =[1]集料筛分及密度!T9 -> 2.6843344 | U30: =级配!F30/S30*E29 -> 0.051520367 | V30: =级配!F30/T30*E29 -> 0.052154455
C31: 粗集料 | D31: 10-15 | F31: 0.13 | G31: 100 | H31: 100 | I31: 99.586446 | J31: 78.910673 | K31: 26.383191 | L31: 0.77822473 | M31: 0.43380263 | N31: 0.30670421 | O31: 0 | P31: 0 | Q31: 0 | R31: 0 | S31: =[1]集料筛分及密度!S10 -> 2.7222877 | T31: =[1]集料筛分及密度!T10 -> 2.6806674 | U31: =级配!F31/S31*E29 -> 0.023876976 | V31: =级配!F31/T31*E29 -> 0.024247693
C32: 粗集料 | D32: 5-10 | F32: 0.13 | G32: 100 | H32: 100 | I32: 100 | J32: 100 | K32: 89.684047 | L32: 3.3944908 | M32: 1.1298305 | N32: 1.0423436 | O32: 0 | P32: 0 | Q32: 0 | R32: 0 | S32: 2.7222877 | T32: 2.6806674 | U32: =级配!F32/S32*E29 -> 0.023876976 | V32: =级配!F32/T32*E29 -> 0.024247693
C33: 粗集料 | D33: 3-5 | F33: 0.13 | G33: 100 | H33: 100 | I33: 100 | J33: 100 | K33: 100 | L33: 95.985683 | M33: 12.69153 | N33: 5.8851935 | O33: 4.1839728 | P33: 3.6277139 | Q33: 3.3515061 | R33: 3.1246478 | S33: 2.7173719 | T33: 2.6843344 | U33: =级配!F33/S33*E29 -> 0.023920171 | V33: =级配!F33/T33*E29 -> 0.024214569
C34: 细集料 | D34: 0-3 | F34: 0.13 | G34: 100 | H34: 100 | I34: 100 | J34: 100 | K34: 100 | L34: 100 | M34: 69.772922 | N34: 41.231077 | O34: 19.951442 | P34: 11.610968 | Q34: 9.3544702 | R34: 7.0408455 | S34: =[1]集料筛分及密度!Z11 -> 2.7402235 | T34: =[1]集料筛分及密度!AA11 -> 2.6452465 | U34: =级配!F34/S34*E29 -> 0.023720693 | V34: =级配!F34/T34*E29 -> 0.024572379
C35: 矿粉 | D35: 矿粉 | F35: 0.02 | G35: 100 | H35: 100 | I35: 100 | J35: 100 | K35: 100 | L35: 100 | M35: 100 | N35: 100 | O35: 100 | P35: 99.7 | Q35: 97.1 | R35: 76.6 | S35: =[1]集料筛分及密度!Z39 -> 2.7292052 | T35: =[1]集料筛分及密度!AA39 -> 2.642669 | U35: =级配!F35/S35*E29 -> 0.0036640704 | V35: =级配!F35/T35*E29 -> 0.0037840532
C36: 粗RAP料 | D36: 10-20 | E36: 0.5 | F36: 0.6 | G36: 100 | H36: 100 | I36: 100 | J36: 92.75 | K36: 55.5 | L36: 23.1 | M36: 18.35 | N36: 13.95 | O36: 10.7 | P36: 8.6 | Q36: 7.55 | R36: 6.25 | S36: =[1]集料筛分及密度!S13 -> 2.7166645 | T36: =[1]集料筛分及密度!T13 -> 2.6933907 | U36: =级配!F36/S36*E36 -> 0.11042954 | V36: =级配!F36/T36*E36 -> 0.11138377 | AE36: 3.2827929
C37: 细RAP料 | D37: 0-10 | F37: 0.4 | G37: 100 | H37: 100 | I37: 100 | J37: 100 | K37: 98.793898 | L37: 81.170722 | M37: 61.440213 | N37: 46.2292 | O37: 32.838359 | P37: 23.463475 | Q37: 19.381251 | R37: 15.171029 | S37: =[1]集料筛分及密度!Z14 -> 2.5628227 | T37: =[1]集料筛分及密度!AA14 -> 2.5337838 | U37: =级配!F37/S37*E36 -> 0.078038952 | V37: =级配!F37/T37*E36 -> 0.078933333 | AE37: 6
F38: 级配1 | G38: =$E$29*($F$29*G29+$F$30*G30+$F$31*G31+$F$32*G32+$F$33*G33+$F$34*G34+$F$35*G35)+$E$36*($F$36*G36+$F$37*G37) -> 99.964 | H38: =E29*(F29*H29+F30*H30+F31*H31+F32*H32+F33*H33+F34*H34+F35*H35)+E36*(F36*H36+F37*H37) -> 91.44271 | I38: =E29*(F29*I29+F30*I30+F31*I31+F32*I32+F33*I33+F34*I34+F35*I35)+E36*(F36*I36+F37*I37) -> 86.284885 | J38: =E29*(F29*J29+F30*J30+F31*J31+F32*J32+F33*J33+F34*J34+F35*J35)+E36*(F36*J36+F37*J37) -> 78.174603 | K38: =E29*(F29*K29+F30*K30+F31*K31+F32*K32+F33*K33+F34*K34+F35*K35)+E36*(F36*K36+F37*K37) -> 58.746005 | L38: =E29*(F29*L29+F30*L30+F31*L31+F32*L32+F33*L33+F34*L34+F35*L35)+E36*(F36*L36+F37*L37) -> 37.237043 | M38: =E29*(F29*M29+F30*M30+F31*M31+F32*M32+F33*M33+F34*M34+F35*M35)+E36*(F36*M36+F37*M37) -> 24.254868 | N38: =E29*(F29*N29+F30*N30+F31*N31+F32*N32+F33*N33+F34*N34+F35*N35)+E36*(F36*N36+F37*N37) -> 17.581086 | O38: =E29*(F29*O29+F30*O30+F31*O31+F32*O32+F33*O33+F34*O34+F35*O35)+E36*(F36*O36+F37*O37) -> 12.346474 | P38: =E29*(F29*P29+F30*P30+F31*P31+F32*P32+F33*P33+F34*P34+F35*P35)+E36*(F36*P36+F37*P37) -> 9.2602093 | Q38: =E29*(F29*Q29+F30*Q30+F31*Q31+F32*Q32+F33*Q33+F34*Q34+F35*Q35)+E36*(F36*Q36+F37*Q37) -> 7.9381387 | R38: =E29*(F29*R29+F30*R30+F31*R31+F32*R32+F33*R33+F34*R34+F35*R35)+E36*(F36*R36+F37*R37) -> 6.3359628
F39: 级配上限 | G39: 100 | H39: 100 | I39: 92 | J39: 80 | K39: 72 | L39: 56 | M39: 44 | N39: 33 | O39: 24 | P39: 17 | Q39: 13 | R39: 7
F40: 级配中值 | G40: =(G39+G41)/2 -> 100 | H40: =(H39+H41)/2 -> 95 | I40: =(I39+I41)/2 -> 85 | J40: =(J39+J41)/2 -> 71 | K40: =(K39+K41)/2 -> 61 | L40: =(L39+L41)/2 -> 41 | M40: =(M39+M41)/2 -> 30 | N40: =(N39+N41)/2 -> 22.5 | ... R40: =(R39+R41)/2 -> 5
...

Sheet 体积指标
A1: 试件来源 | B1: 级配类型 | C1: 试件类型 | D1: 试件名称 | E1: 沥青混合料最大理论相对密度/(g/cm3) | F1: 矿料的合成毛体积相对密度/(g/cm3) | G1: 油石比/% | H1: 沥青用量/% | I1: 实验数据 | S1: 计算数据 | X1: 均值 | AC1: 60℃动力粘度/Pa·s | AD1: 针入度 | AE1: 软化点 | AF1: 残留延度（10℃）
I2: 干重/g | J2: 水中重/g | K2: 表干重/g | L2: 高度1/mm | M2: 高度2/mm | N2: 高度3/mm | O2: 高度4/mm | P2: 均值/mm | Q2: 稳定度/kN | R2: 流值/mm | S2: 毛体积密度/(g/cm3) | T2: 毛体积相对密度/(g/cm3) | U2: 空隙率/% | V2: 矿料间隙率/% | W2: 沥青饱和度/% | X2: 毛体积密度/(g/cm3) | Y2: 毛体积相对密度/(g/cm3) | Z2: 空隙率/% | AA2: 矿料间隙率/% | AB2: 沥青饱和度/%
A3: A | B3: 90# AC-20-1 | C3: 90#1（90#） | D3: 试件1 | E3: 2.5732813 | F3: 2.6661282 | G3: =100*H3/(100-H3) -> 4.3 | H3: 4.1227229 | I3: 1199.8 | J3: 715.7 | K3: 1205.3 | L3: 64.3 | M3: 63.8 | N3: 64.3 | O3: / | P3: 64.133333 | Q3: 14.03 | R3: 3.34 | S3: =I3/(K3-J3) -> 2.4505719 | T3: =0.9971*S3 -> 2.4434652 | U3: =100*(1-T3/E3) -> 5.0447667 | V3: =100-T3*(100-H3)/F3 -> 12.129961 | W3: =100*(V3-U3)/V3 -> 58.410692 | X3: =AVERAGE(S3:S7) -> 2.4620301 | Y3: =AVERAGE(T3:T7) -> 2.4548902 | Z3: =AVERAGE(U3:U7) -> 4.6007809 | AA3: =AVERAGE(V3:V7) -> 11.719103 | AB3: =AVERAGE(W3:W7) -> 60.874133 | AC3: 161 | AD3: 91 | AE3: 44 | AF3: 15
A4: A | C4: 90#1（90#） | D4: 试件2 | E4: 2.5732813 | F4: 2.6661282 | G4: =100*H4/(100-H4) -> 4.3 | H4: 4.1227229 | I4: 1205.1 | J4: 718 | K4: 1209.7 | L4: 63.9 | M4: 64.1 | N4: 64 | O4: / | P4: 64 | Q4: 12.47 | R4: 2.87 | S4: =I4/(K4-J4) -> 2.4508847 | T4: =0.9971*S4 -> 2.4437771 | U4: =100*(1-T4/E4) -> 5.0326466 | V4: =100-T4*(100-H4)/F4 -> 12.118745 | W4: =100*(V4-U4)/V4 -> 58.472213 | AC4: 161 | AD4: 91 | AE4: 44 | AF4: 15
A5: A | C5: 90#1（90#） | D5: 试件3 | E5: 2.5732813 | F5: 2.6661282 | G5: =100*H5/(100-H5) -> 4.3 | H5: 4.1227229 | I5: 1199.4 | J5: 716.3 | K5: 1202.6 | L5: 63 | M5: 63.4 | N5: 63.1 | O5: / | P5: 63.166667 | Q5: 14.58 | R5: 3.88 | S5: =I5/(K5-J5) -> 2.4663788 | T5: =0.9971*S5 -> 2.4592263 | U5: =100*(1-T5/E5) -> 4.4322785 | V5: =100-T5*(100-H5)/F5 -> 11.563174 | W5: =100*(V5-U5)/V5 -> 61.669015 | AC5: 161 | AD5: 91 | AE5: 44 | AF5: 15
A6: A | C6: 90#1（90#） | D6: 试件4 | E6: 2.5732813 | F6: 2.6661282 | G6: =100*H6/(100-H6) -> 4.3 | H6: 4.1227229 | I6: 1199.1 | J6: 715.1 | K6: 1203.6 | L6: 63.7 | M6: 63.4 | N6: 63.5 | O6: / | P6: 63.533333 | Q6: 15.7 | R6: 3.93 | S6: =I6/(K6-J6) -> 2.4546571 | T6: =0.9971*S6 -> 2.4475386 | U6: =100*(1-T6/E6) -> 4.8864718 | V6: =100-T6*(100-H6)/F6 -> 11.983477 | W6: =100*(V6-U6)/V6 -> 59.223256 | AC6: 161 | AD6: 91 | AE6: 44 | AF6: 15
A7: A | C7: 90#1（90#） | D7: 试件5 | E7: 2.5732813 | F7: 2.6661282 | G7: =100*H7/(100-H7) -> 4.3 | H7: 4.1227229 | I7: 1199.3 | J7: 719.9 | K7: 1202 | L7: 61.7 | M7: 61.7 | N7: 61.9 | O7: / | P7: 61.766667 | Q7: 15.52 | R7: 2.88 | S7: =I7/(K7-J7) -> 2.4876582 | T7: =0.9971*S7 -> 2.480444 | U7: =100*(1-T7/E7) -> 3.6077408 | V7: =100-T7*(100-H7)/F7 -> 10.80016 | W7: =100*(V7-U7)/V7 -> 66.595488 | AC7: 161 | AD7: 91 | AE7: 44 | AF7: 15
A8: A | C8: 90#1（实验室自制） | D8: 试件1 | E8: 2.5732813 | F8: 2.6661282 | G8: =100*H8/(100-H8) -> 4.3 | H8: 4.1227229 | I8: 1202.2 | J8: 711 | K8: 1210.1 | L8: 65.1 | M8: 65.3 | N8: 65.1 | O8: / | P8: 65.166667 | Q8: 13.55 | R8: 2.96 | S8: =I8/(K8-J8) -> 2.4087357 | T8: =0.9971*S8 -> 2.4017504 | U8: =100*(1-T8/E8) -> 6.6658427 | V8: =100-T8*(100-H8)/F8 -> 13.630078 | W8: =100*(V8-U8)/V8 -> 51.094612 | X8: =AVERAGE(S8:S12) -> 2.440652 | Y8: =AVERAGE(T8:T12) -> 2.4335741 | Z8: =AVERAGE(U8:U12) -> 5.4291436 | AA8: =AVERAGE(V8:V12) -> 12.485657 | AB8: =AVERAGE(W8:W12) -> 56.729326 | AC8: 161 | AD8: 91 | AE8: 44 | AF8: 15
A9: A | C9: 90#1（实验室自制） | D9: 试件2 | E9: 2.5732813 | F9: 2.6661282 | G9: =100*H9/(100-H9) -> 4.3 | H9: 4.1227229 | I9: 1196.1 | J9: 712.3 | K9: 1202.7 | L9: 63.9 | M9: 64 | N9: 63.8 | O9: / | P9: 63.9 | Q9: 13.15 | R9: 3.27 | S9: =I9/(K9-J9) -> 2.4390294 | T9: =0.9971*S9 -> 2.4319562 | U9: =100*(1-T9/E9) -> 5.4920189 | V9: =100-T9*(100-H9)/F9 -> 12.543841 | W9: =100*(V9-U9)/V9 -> 56.217405 | AC9: 161 | AD9: 91 | AE9: 44 | AF9: 15
A10: A | C10: 90#1（实验室自制） | D10: 试件3 | E10: 2.5732813 | F10: 2.6661282 | G10: =100*H10/(100-H10) -> 4.3 | H10: 4.1227229 | I10: 1198.4 | J10: 711.9 | K10: 1204.3 | L10: 63.8 | M10: 63.9 | N10: 63.7 | O10: / | P10: 63.8 | Q10: 16.33 | R10: 4.44 | S10: =I10/(K10-J10) -> 2.4337937 | T10: =0.9971*S10 -> 2.4267357 | U10: =100*(1-T10/E10) -> 5.6948928 | V10: =100-T10*(100-H10)/F10 -> 12.731577 | W10: =100*(V10-U10)/V10 -> 55.269541 | AC10: 161 | AD10: 91 | AE10: 44 | AF10: 15
A11: A | C11: 90#1（实验室自制） | D11: 试件4 | E11: 2.5732813 | F11: 2.6661282 | G11: =100*H11/(100-H11) -> 4.3 | H11: 4.1227229 | I11: 1196.6 | J11: 712.9 | K11: 1200.7 | L11: 63 | M11: 62.7 | N11: 63 | O11: / | P11: 62.9 | Q11: 15.78 | R11: 3.05 | S11: =I11/(K11-J11) -> 2.4530545 | T11: =0.9971*S11 -> 2.4459407 | U11: =100*(1-T11/E11) -> 4.948569 | V11: =100-T11*(100-H11)/F11 -> 12.040941 | W11: =100*(V11-U11)/V11 -> 58.90214 | AC11: 161 | AD11: 91 | AE11: 44 | AF11: 15
A12: A | C12: 90#1（实验室自制） | D12: 试件5 | E12: 2.5732813 | F12: 2.6661282 | G12: =100*H12/(100-H12) -> 4.3 | H12: 4.1227229 | I12: 1196.8 | J12: 715.9 | K12: 1200.7 | L12: 62.2 | M12: 62.2 | N12: 62.2 | O12: / | P12: 62.2 | Q12: 16.47 | R12: 4.46 | S12: =I12/(K12-J12) -> 2.4686469 | T12: =0.9971*S12 -> 2.4614878 | U12: =100*(1-T12/E12) -> 4.3443943 | V12: =100-T12*(100-H12)/F12 -> 11.481847 | W12: =100*(V12-U12)/V12 -> 62.162933 | AC12: 161 | AD12: 91 | AE12: 44 | AF12: 15
A13: A | C13: 90#1（实验室自制） | D13: 试件6 | E13: 2.5732813 | F13: 2.6661282 | G13: =100*H13/(100-H13) -> 4.3 | H13: 4.1227229 | I13: 1210.4 | J13: 722.3 | K13: 1214.2 | L13: 63.5 | M13: 63.5 | N13: 63.6 | O13: / | P13: 63.533333 | Q13: 17.24 | R13: 2.85 | S13: =I13/(K13-J13) -> 2.4606627 | T13: =0.9971*S13 -> 2.4535268 | U13: =100*(1-T13/E13) -> 4.6537648 | V13: =100-T13*(100-H13)/F13 -> 11.768134 | W13: =100*(V13-U13)/V13 -> 60.454522 | AC13: 161 | AD13: 91 | AE13: 44 | AF13: 15
A14: A | B14: 90# AC-20-2 | C14: 90#2（90#对比） | D14: 试件1 | E14: 2.5732813 | F14: 2.6661282 | G14: =100*H14/(100-H14) -> 4.3 | H14: 4.1227229 | I14: 1201.5 | J14: 719.1 | K14: 1208.3 | L14: 64 | M14: 64 | N14: 64 | O14: / | P14: 64 | Q14: 16.14 | R14: 3.77 | S14: =I14/(K14-J14) -> 2.4560507 | T14: =0.9971*S14 -> 2.4489281 | U14: =100*(1-T14/E14) -> 4.8324731 | V14: =100-T14*(100-H14)/F14 -> 11.933508 | W14: =100*(V14-U14)/V14 -> 59.505007 | X14: =AVERAGE(S14:S18) -> 2.4849787 | Y14: =AVERAGE(T14:T18) -> 2.4777722 | Z14: =AVERAGE(U14:U18) -> 3.7115669 | AA14: =AVERAGE(V14:V18) -> 10.896239 | AB14: =AVERAGE(W14:W18) -> 66.434485 | AC14: 161 | AD14: 91 | AE14: 44 | AF14: 15
A15: A | C15: 90#2（90#对比） | D15: 试件2 | E15: 2.5732813 | F15: 2.6661282 | G15: =100*H15/(100-H15) -> 4.3 | H15: 4.1227229 | I15: 1198.5 | J15: 716.2 | K15: 1204.2 | L15: 63 | M15: 63.2 | N15: 63 | O15: / | P15: 63.066667 | Q15: 14.1 | R15: 3.42 | S15: =I15/(K15-J15) -> 2.4559426 | T15: =0.9971*S15 -> 2.4488204 | U15: =100*(1-T15/E15) -> 4.8366607 | V15: =100-T15*(100-H15)/F15 -> 11.937383 | W15: =100*(V15-U15)/V15 -> 59.483073 | AC15: 161 | AD15: 91 | AE15: 44 | AF15: 15
A16: A | C16: 90#2（90#对比） | D16: 试件3 | E16: 2.5732813 | F16: 2.6661282 | G16: =100*H16/(100-H16) -> 4.3 | H16: 4.1227229 | I16: 1195.4 | J16: 720.5 | K16: 1200.6 | L16: 62.2 | M16: 62.2 | N16: 62.2 | O16: / | P16: 62.2 | Q16: 14.27 | R16: 2.79 | S16: =I16/(K16-J16) -> 2.4898979 | T16: =0.9971*S16 -> 2.4826772 | U16: =100*(1-T16/E16) -> 3.5209536 | V16: =100-T16*(100-H16)/F16 -> 10.719849 | W16: =100*(V16-U16)/V16 -> 67.15482 | AC16: 161 | AD16: 91 | AE16: 44 | AF16: 15
A17: A | C17: 90#2（90#对比） | D17: 试件4 | E17: 2.5732813 | F17: 2.6661282 | G17: =100*H17/(100-H17) -> 4.3 | H17: 4.1227229 | I17: 1208.5 | J17: 729.4 | K17: 1210.8 | L17: 61 | M17: 61 | N17: 61 | O17: / | P17: 61 | Q17: 16.79 | R17: 5.71 | S17: =I17/(K17-J17) -> 2.5103864 | T17: =0.9971*S17 -> 2.5031063 | U17: =100*(1-T17/E17) -> 2.7270637 | V17: =100-T17*(100-H17)/F17 -> 9.9851958 | W17: =100*(V17-U17)/V17 -> 72.688931 | AC17: 161 | AD17: 91 | AE17: 44 | AF17: 15
A18: A | C18: 90#2（90#对比） | D18: 试件5 | E18: 2.5732813 | F18: 2.6661282 | G18: =100*H18/(100-H18) -> 4.3 | H18: 4.1227229 | I18: 1195 | J18: 722.5 | K18: 1198.1 | L18: 61 | M18: 61 | N18: 61 | O18: / | P18: 61 | Q18: 16.05 | R18: 4.54 | S18: =I18/(K18-J18) -> 2.5126156 | T18: =0.9971*S18 -> 2.5053291 | U18: =100*(1-T18/E18) -> 2.6406835 | V18: =100-T18*(100-H18)/F18 -> 9.9052609 | W18: =100*(V18-U18)/V18 -> 73.340596 | AC18: 161 | AD18: 91 | AE18: 44 | AF18: 15
A19: A | C19: 90#2（90#对比） | D19: 试件6 | E19: 2.5732813 | F19: 2.6661282 | G19: =100*H19/(100-H19) -> 4.3 | H19: 4.1227229 | I19: 1201.3 | J19: 725.4 | K19: 1205.2 | L19: 61.4 | M19: 61.1 | N19: 61.8 | O19: / | P19: 61.433333 | Q19: 16.58 | R19: 5.18 | S19: =I19/(K19-J19) -> 2.5037516 | T19: =0.9971*S19 -> 2.4964907 | U19: =100*(1-T19/E19) -> 2.9841506 | V19: =100-T19*(100-H19)/F19 -> 10.2231 | W19: =100*(V19-U19)/V19 -> 70.809728 | AC19: 161 | AD19: 91 | AE19: 44 | AF19: 15
A20: B | B20: AC-20 | C20: 方案一90# | D20: 试件1 | E20: 2.544 | F20: 2.6540905 | G20: =100*H20/(100-H20) -> 4.2 | H20: 4.0307102 | I20: 1233.5 | J20: 730.9 | K20: 1235.7 | L20: 64.67 | M20: 64.3 | N20: 64.58 | O20: 64.26 | P20: 64.4525 | Q20: 16.88 | R20: 2.14 | S20: =I20/(K20-J20) -> 2.443542 | T20: =0.9971*S20 -> 2.4364557 | U20: =100*(1-T20/E20) -> 4.2273693 | V20: =100-T20*(100-H20)/F20 -> 11.900167 | W20: =100*(V20-U20)/V20 -> 64.476387 | X20: =AVERAGE(S20:S24) -> 2.4394388 | Y20: =AVERAGE(T20:T24) -> 2.4323644 | Z20: =AVERAGE(U20:U24) -> 4.3881925 | AA20: =AVERAGE(V20:V24) -> 12.048106 | AB20: =AVERAGE(W20:W24) -> 63.595091 | AC20: 161 | AD20: 91 | AE20: 44 | AF20: 15
A21: B | C21: 方案一90# | D21: 试件2 | E21: 2.544 | F21: 2.6540905 | G21: =100*H21/(100-H21) -> 4.2 | H21: 4.0307102 | I21: 1220.7 | J21: 721.3 | K21: 1221.9 | L21: 63.56 | M21: 63.55 | N21: 63.41 | O21: 63.6 | P21: 63.53 | Q21: 15.6 | R21: 2.65 | S21: =I21/(K21-J21) -> 2.4384738 | T21: =0.9971*S21 -> 2.4314023 | U21: =100*(1-T21/E21) -> 4.4260119 | V21: =100-T21*(100-H21)/F21 -> 12.082895 | W21: =100*(V21-U21)/V21 -> 63.369609 | AC21: 161 | AD21: 91 | AE21: 44 | AF21: 15
A22: B | C22: 方案一90# | D22: 试件3 | E22: 2.544 | F22: 2.6540905 | G22: =100*H22/(100-H22) -> 4.2 | H22: 4.0307102 | I22: 1221 | J22: 723.5 | K22: 1222.6 | L22: 63.79 | M22: 63.49 | N22: 63.76 | O22: 63.49 | P22: 63.6325 | Q22: 17.02 | R22: 2.47 | S22: =I22/(K22-J22) -> 2.4464035 | T22: =0.9971*S22 -> 2.439309 | U22: =100*(1-T22/E22) -> 4.115214 | V22: =100-T22*(100-H22)/F22 -> 11.796997 | W22: =100*(V22-U22)/V22 -> 65.116428 | AC22: 161 | AD22: 91 | AE22: 44 | AF22: 15
A23: B | C23: 方案一90# | D23: 试件4 | E23: 2.544 | F23: 2.6540905 | G23: =100*H23/(100-H23) -> 4.2 | H23: 4.0307102 | I23: 1220.6 | J23: 721.6 | K23: 1222.4 | L23: 63.85 | M23: 63.56 | N23: 63.57 | O23: 63.51 | P23: 63.6225 | Q23: 15.67 | R23: 2.27 | S23: =I23/(K23-J23) -> 2.4373003 | T23: =0.9971*S23 -> 2.4302321 | U23: =100*(1-T23/E23) -> 4.4720067 | V23: =100-T23*(100-H23)/F23 -> 12.125205 | W23: =100*(V23-U23)/V23 -> 63.118095 | AC23: 161 | AD23: 91 | AE23: 44 | AF23: 15
A24: B | C24: 方案一90# | D24: 试件5 | E24: 2.544 | F24: 2.6540905 | G24: =100*H24/(100-H24) -> 4.2 | H24: 4.0307102 | I24: 1220.6 | J24: 721.5 | K24: 1223.5 | L24: 65.06 | M24: 64.96 | N24: 65.07 | O24: 64.78 | P24: 64.9675 | Q24: 14.27 | R24: 2.6 | S24: =I24/(K24-J24) -> 2.4314741 | T24: =0.9971*S24 -> 2.4244228 | U24: =100*(1-T24/E24) -> 4.7003605 | V24: =100-T24*(100-H24)/F24 -> 12.335265 | W24: =100*(V24-U24)/V24 -> 61.894936 | AC24: 161 | AD24: 91 | AE24: 44 | AF24: 15
A25: B | C25: 方案二90# | D25: 试件1 | E25: 2.544 | F25: 2.6540905 | G25: =100*H25/(100-H25) -> 4.2 | H25: 4.0307102 | I25: 1233.1 | J25: 730.6 | K25: 1235.3 | L25: 63.1 | M25: 63.42 | N25: 63.43 | O25: 63.21 | P25: 63.29 | Q25: 14.49 | R25: 3.09 | S25: =I25/(K25-J25) -> 2.4432336 | T25: =0.9971*S25 -> 2.4361482 | U25: =100*(1-T25/E25) -> 4.2394565 | V25: =100-T25*(100-H25)/F25 -> 11.911286 | W25: =100*(V25-U25)/V25 -> 64.40807 | X25: =AVERAGE(S25:S29) -> 2.4432675 | Y25: =AVERAGE(T25:T29) -> 2.436182 | Z25: =AVERAGE(U25:U29) -> 4.2381274 | AA25: =AVERAGE(V25:V29) -> 11.910063 | AB25: =AVERAGE(W25:W29) -> 64.420207 | AC25: 161 | AD25: 91 | AE25: 44 | AF25: 15
A26: B | C26: 方案二90# | D26: 试件2 | E26: 2.544 | F26: 2.6540905 | G26: =100*H26/(100-H26) -> 4.2 | H26: 4.0307102 | I26: 1233.5 | J26: 730.8 | K26: 1235.6 | L26: 62.68 | M26: 62.58 | N26: 62.77 | O26: 62.84 | P26: 62.7175 | Q26: 15.41 | R26: 3.47 | S26: =I26/(K26-J26) -> 2.443542 | T26: =0.9971*S26 -> 2.4364557 | U26: =100*(1-T26/E26) -> 4.2273693 | V26: =100-T26*(100-H26)/F26 -> 11.900167 | W26: =100*(V26-U26)/V26 -> 64.476387 | AC26: 161 | AD26: 91 | AE26: 44 | AF26: 15
A27: B | C27: 方案二90# | D27: 试件3 | E27: 2.544 | F27: 2.6540905 | G27: =100*H27/(100-H27) -> 4.2 | H27: 4.0307102 | I27: 1237.3 | J27: 732.8 | K27: 1239.2 | L27: 62.88 | M27: 63.09 | N27: 63.07 | O27: 62.96 | P27: 63 | Q27: 15.76 | R27: 2.19 | S27: =I27/(K27-J27) -> 2.4433254 | T27: =0.9971*S27 -> 2.4362398 | U27: =100*(1-T27/E27) -> 4.2358573 | V27: =100-T27*(100-H27)/F27 -> 11.907975 | W27: =100*(V27-U27)/V27 -> 64.4284 | AC27: 161 | AD27: 91 | AE27: 44 | AF27: 15
A28: B | C28: 方案二90# | D28: 试件4 | E28: 2.544 | F28: 2.6540905 | G28: =100*H28/(100-H28) -> 4.2 | H28: 4.0307102 | I28: 1236.8 | J28: 731.7 | K28: 1238.8 | L28: 63.5 | M28: 63.47 | N28: 63.39 | O28: 63.27 | P28: 63.4075 | Q28: 14.38 | R28: 3.45 | S28: =I28/(K28-J28) -> 2.4389667 | T28: =0.9971*S28 -> 2.4318937 | U28: =100*(1-T28/E28) -> 4.4066954 | V28: =100-T28*(100-H28)/F28 -> 12.065126 | W28: =100*(V28-U28)/V28 -> 63.475763 | AC28: 161 | AD28: 91 | AE28: 44 | AF28: 15
A29: B | C29: 方案二90# | D29: 试件5 | E29: 2.544 | F29: 2.6540905 | G29: =100*H29/(100-H29) -> 4.2 | H29: 4.0307102 | I29: 1241.5 | J29: 735.7 | K29: 1243 | L29: 63.81 | M29: 63.95 | N29: 63.93 | O29: 63.64 | P29: 63.8325 | Q29: 14.19 | R29: 3.06 | S29: =I29/(K29-J29) -> 2.4472699 | T29: =0.9971*S29 -> 2.4401728 | U29: =100*(1-T29/E29) -> 4.0812587 | V29: =100-T29*(100-H29)/F29 -> 11.765762 | W29: =100*(V29-U29)/V29 -> 65.312415 | AC29: 161 | AD29: 91 | AE29: 44 | AF29: 15
A30: B | C30: 方案三90# | D30: 试件1 | E30: 2.544 | F30: 2.6540905 | G30: =100*H30/(100-H30) -> 4.2 | H30: 4.0307102 | I30: 1233.7 | J30: 730.3 | K30: 1235.8 | L30: 62.28 | M30: 62.41 | N30: 62.53 | O30: 62.3 | P30: 62.38 | Q30: 18.5 | R30: 2.68 | S30: =I30/(K30-J30) -> 2.4405539 | T30: =0.9971*S30 -> 2.4334763 | U30: =100*(1-T30/E30) -> 4.344485 | V30: =100-T30*(100-H30)/F30 -> 12.0079 | W30: =100*(V30-U30)/V30 -> 63.819777 | X30: =AVERAGE(S30:S34) -> 2.4446959 | Y30: =AVERAGE(T30:T34) -> 2.4376063 | Z30: =AVERAGE(U30:U34) -> 4.1821425 | AA30: =AVERAGE(V30:V34) -> 11.858564 | AB30: =AVERAGE(W30:W34) -> 64.740484 | AC30: 161 | AD30: 91 | AE30: 44 | AF30: 15
A31: B | C31: 方案三90# | D31: 试件2 | E31: 2.544 | F31: 2.6540905 | G31: =100*H31/(100-H31) -> 4.2 | H31: 4.0307102 | I31: 1235.7 | J31: 732.3 | K31: 1237.8 | L31: 62.9 | M31: 62.79 | N31: 62.83 | O31: 62.72 | P31: 62.81 | Q31: 17.59 | R31: 2.65 | S31: =I31/(K31-J31) -> 2.4445104 | T31: =0.9971*S31 -> 2.4374213 | U31: =100*(1-T31/E31) -> 4.1894141 | V31: =100-T31*(100-H31)/F31 -> 11.865253 | W31: =100*(V31-U31)/V31 -> 64.691741 | AC31: 161 | AD31: 91 | AE31: 44 | AF31: 15
A32: B | C32: 方案三90# | D32: 试件3 | E32: 2.544 | F32: 2.6540905 | G32: =100*H32/(100-H32) -> 4.2 | H32: 4.0307102 | I32: 1238.7 | J32: 733.6 | K32: 1240.8 | L32: 62.47 | M32: 62.66 | N32: 62.85 | O32: 62.65 | P32: 62.6575 | Q32: 17.48 | R32: 2.54 | S32: =I32/(K32-J32) -> 2.4422319 | T32: =0.9971*S32 -> 2.4351494 | U32: =100*(1-T32/E32) -> 4.278719 | V32: =100-T32*(100-H32)/F32 -> 11.947403 | W32: =100*(V32-U32)/V32 -> 64.187037 | AC32: 161 | AD32: 91 | AE32: 44 | AF32: 15
A33: B | C33: 方案三90# | D33: 试件4 | E33: 2.544 | F33: 2.6540905 | G33: =100*H33/(100-H33) -> 4.2 | H33: 4.0307102 | I33: 1242.9 | J33: 737.3 | K33: 1244.6 | L33: 63.91 | M33: 63.58 | N33: 63.85 | O33: 63.9 | P33: 63.81 | Q33: 16.24 | R33: 2.19 | S33: =I33/(K33-J33) -> 2.4500296 | T33: =0.9971*S33 -> 2.4429245 | U33: =100*(1-T33/E33) -> 3.9730942 | V33: =100-T33*(100-H33)/F33 -> 11.666263 | W33: =100*(V33-U33)/V33 -> 65.943729 | AC33: 161 | AD33: 91 | AE33: 44 | AF33: 15
A34: B | C34: 方案三90# | D34: 试件5 | E34: 2.544 | F34: 2.6540905 | G34: =100*H34/(100-H34) -> 4.2 | H34: 4.0307102 | I34: 1240.2 | J34: 735.1 | K34: 1242.1 | L34: 64.05 | M34: 64 | N34: 63.87 | O34: 63.8 | P34: 63.93 | Q34: 17.28 | R34: 2.32 | S34: =I34/(K34-J34) -> 2.4461538 | T34: =0.9971*S34 -> 2.43906 | U34: =100*(1-T34/E34) -> 4.125 | V34: =100-T34*(100-H34)/F34 -> 11.805999 | W34: =100*(V34-U34)/V34 -> 65.060136 | AC34: 161 | AD34: 91 | AE34: 44 | AF34: 15
A35: B | C35: 方案五90# | D35: 试件1 | E35: 2.544 | F35: 2.6540905 | G35: =100*H35/(100-H35) -> 4.2 | H35: 4.0307102 | I35: 1221.8 | J35: 723.1 | K35: 1224.3 | L35: 62.28 | M35: 62.41 | N35: 62.53 | O35: 62.3 | P35: 62.38 | Q35: 15.26 | R35: 2.65 | S35: =I35/(K35-J35) -> 2.4377494 | T35: =0.9971*S35 -> 2.4306799 | U35: =100*(1-T35/E35) -> 4.4544053 | V35: =100-T35*(100-H35)/F35 -> 12.109014 | W35: =100*(V35-U35)/V35 -> 63.214137 | X35: =AVERAGE(S35:S39) -> 2.4358271 | Y35: =AVERAGE(T35:T39) -> 2.4287632 | Z35: =AVERAGE(U35:U39) -> 4.5297487 | AA35: =AVERAGE(V35:V39) -> 12.178321 | AB35: =AVERAGE(W35:W39) -> 62.810273 | AC35: 161 | AD35: 91 | AE35: 44 | AF35: 15
A36: B | C36: 方案五90# | D36: 试件2 | E36: 2.544 | F36: 2.6540905 | G36: =100*H36/(100-H36) -> 4.2 | H36: 4.0307102 | I36: 1220 | J36: 722.1 | K36: 1223.3 | L36: 62.9 | M36: 62.79 | N36: 62.83 | O36: 62.72 | P36: 62.81 | Q36: 15.39 | R36: 2.11 | S36: =I36/(K36-J36) -> 2.434158 | T36: =0.9971*S36 -> 2.427099 | U36: =100*(1-T36/E36) -> 4.5951666 | V36: =100-T36*(100-H36)/F36 -> 12.238498 | W36: =100*(V36-U36)/V36 -> 62.453183 | AC36: 161 | AD36: 91 | AE36: 44 | AF36: 15
A37: B | C37: 方案五90# | D37: 试件3 | E37: 2.544 | F37: 2.6540905 | G37: =100*H37/(100-H37) -> 4.2 | H37: 4.0307102 | I37: 1218.2 | J37: 720.2 | K37: 1221.1 | L37: 62.47 | M37: 62.66 | N37: 62.85 | O37: 62.65 | P37: 62.6575 | Q37: 14.05 | R37: 2.23 | S37: =I37/(K37-J37) -> 2.4320224 | T37: =0.9971*S37 -> 2.4249695 | U37: =100*(1-T37/E37) -> 4.6788721 | V37: =100-T37*(100-H37)/F37 -> 12.315498 | W37: =100*(V37-U37)/V37 -> 62.008259 | AC37: 161 | AD37: 91 | AE37: 44 | AF37: 15
A38: B | C38: 方案五90# | D38: 试件4 | E38: 2.544 | F38: 2.6540905 | G38: =100*H38/(100-H38) -> 4.2 | H38: 4.0307102 | I38: 1218.6 | J38: 720.7 | K38: 1221.2 | L38: 63.91 | M38: 63.58 | N38: 63.85 | O38: 63.9 | P38: 63.81 | Q38: 14.19 | R38: 2.26 | S38: =I38/(K38-J38) -> 2.4347652 | T38: =0.9971*S38 -> 2.4277044 | U38: =100*(1-T38/E38) -> 4.5713673 | V38: =100-T38*(100-H38)/F38 -> 12.216606 | W38: =100*(V38-U38)/V38 -> 62.580709 | AC38: 161 | AD38: 91 | AE38: 44 | AF38: 15
A39: B | C39: 方案五90# | D39: 试件5 | E39: 2.544 | F39: 2.6540905 | G39: =100*H39/(100-H39) -> 4.2 | H39: 4.0307102 | I39: 1219 | J39: 721.8 | K39: 1221.3 | L39: 64.05 | M39: 64 | N39: 63.87 | O39: 63.8 | P39: 63.93 | Q39: 14.74 | R39: 2.56 | S39: =I39/(K39-J39) -> 2.4404404 | T39: =0.9971*S39 -> 2.4333632 | U39: =100*(1-T39/E39) -> 4.3489323 | V39: =100-T39*(100-H39)/F39 -> 12.011991 | W39: =100*(V39-U39)/V39 -> 63.795076 | AC39: 161 | AD39: 91 | AE39: 44 | AF39: 15
A40: B | C40: 110# | D40: 试件1 | E40: 2.544 | F40: 2.6540905 | G40: =100*H40/(100-H40) -> 4.2 | H40: 4.0307102 | I40: 1235.7 | J40: 736 | K40: 1238.2 | L40: 64.3 | M40: 64.59 | N40: 64.67 | O40: 64.32 | P40: 64.47 | Q40: 14.66 | R40: 2.5 | S40: =I40/(K40-J40) -> 2.4605735 | T40: =0.9971*S40 -> 2.4534378 | U40: =100*(1-T40/E40) -> 3.5598344 | V40: =100-T40*(100-H40)/F40 -> 11.286111 | W40: =100*(V40-U40)/V40 -> 68.458274 | X40: =AVERAGE(S40:S44) -> 2.4569757 | Y40: =AVERAGE(T40:T44) -> 2.4498505 | Z40: =AVERAGE(U40:U44) -> 3.7008445 | AA40: =AVERAGE(V40:V44) -> 11.415825 | AB40: =AVERAGE(W40:W44) -> 67.591917 | AC40: 144 | AD40: 107.8 | AE40: 43.95 | AF40: 60.3
...

Sheet 浸水马歇尔
A1: 试件来源 | B1: 级配类型 | C1: 试件类型 | D1: 试件名称 | E1: 油石比/% | F1: 沥青用量/% | G1: 实验数据 | Q1: 计算数据 | R1: 60℃动力粘度 | S1: 针入度 | T1: 软化点 | U1: 残留延度(10℃)
G2: 干重/g | H2: 水中重/g | I2: 表干重/g | J2: 高度1/mm | K2: 高度2/mm | L2: 高度3/mm | M2: 高度4/mm | N2: 均值/mm | O2: 稳定度/kN | P2: 流值/mm | Q2: 残留稳定度/%
A3: A | B3: 90# AC-20-1 | C3: 90#1（实验室自制） | D3: 试件1（浸） | E3: =100*F3/(100-F3) -> 4.5 | F3: 4.3062201 | G3: / | H3: / | I3: / | J3: 63.5 | K3: 63.6 | L3: 63.9 | M3: / | N3: =AVERAGE(J3:L3) -> 63.666667 | O3: 13.52 | P3: 4.24 | Q3: =100*AVERAGE(O3,O5,O7)/AVERAGEA(O4,O6) -> 79.296129 | R3: 161 | S3: 91 | T3: 44 | U3: 15
A4: A | C4: 90#1（实验室自制） | D4: 试件2 | E4: =100*F4/(100-F4) -> 4.5 | F4: 4.3062201 | G4: / | H4: / | I4: / | J4: 63.2 | K4: 63.2 | L4: 63 | M4: / | N4: =AVERAGE(J4:L4) -> 63.133333 | O4: 17.7 | P4: 6.21 | R4: 161 | S4: 91 | T4: 44 | U4: 15
A5: A | C5: 90#1（实验室自制） | D5: 试件3（浸） | E5: =100*F5/(100-F5) -> 4.5 | F5: 4.3062201 | G5: / | H5: / | I5: / | J5: 63.1 | K5: 63 | L5: 63.1 | M5: / | N5: =AVERAGE(J5:L5) -> 63.066667 | O5: 13.39 | P5: 3.3 | R5: 161 | S5: 91 | T5: 44 | U5: 15
A6: A | C6: 90#1（实验室自制） | D6: 试件4 | E6: =100*F6/(100-F6) -> 4.5 | F6: 4.3062201 | G6: / | H6: / | I6: / | J6: 63.3 | K6: 63.1 | L6: 63.3 | M6: / | N6: =AVERAGE(J6:L6) -> 63.233333 | O6: 15.45 | P6: 3.65 | R6: 161 | S6: 91 | T6: 44 | U6: 15
A7: A | B7: 90# AC-20-2 | C7: 90#2（90#对比） | D7: 试件1（浸） | E7: =100*F7/(100-F7) -> 4.5 | F7: 4.3062201 | G7: / | H7: / | I7: / | J7: 61.8 | K7: 61.8 | L7: 62.2 | M7: / | N7: =AVERAGE(J7:L7) -> 61.933333 | O7: 12.52 | P7: 4.1 | Q7: =100*AVERAGE(O7,O9,O8)/AVERAGEA(O11,O10) -> 86.436934 | R7: 161 | S7: 91 | T7: 44 | U7: 15
A8: A | C8: 90#2（90#对比） | D8: 试件2（浸） | E8: =100*F8/(100-F8) -> 4.5 | F8: 4.3062201 | G8: / | H8: / | I8: / | J8: 61 | K8: 61.6 | L8: 60.9 | M8: / | N8: =AVERAGE(J8:L8) -> 61.166667 | O8: 13 | P8: 5.74 | R8: 161 | S8: 91 | T8: 44 | U8: 15
A9: A | C9: 90#2（90#对比） | D9: 试件3（浸） | E9: =100*F9/(100-F9) -> 4.5 | F9: 4.3062201 | G9: / | H9: / | I9: / | J9: 63.4 | K9: 63.4 | L9: 63.2 | M9: / | N9: =AVERAGE(J9:L9) -> 63.333333 | O9: 13.61 | P9: 4.08 | R9: 161 | S9: 91 | T9: 44 | U9: 15
A10: A | C10: 90#2（90#对比） | D10: 试件4 | E10: =100*F10/(100-F10) -> 4.5 | F10: 4.3062201 | G10: / | H10: / | I10: / | J10: 61.4 | K10: 61.6 | L10: 61.5 | M10: / | N10: =AVERAGE(J10:L10) -> 61.5 | O10: 16.02 | P10: 5.02 | R10: 161 | S10: 91 | T10: 44 | U10: 15
A11: A | C11: 90#2（90#对比） | D11: 试件5 | E11: =100*F11/(100-F11) -> 4.5 | F11: 4.3062201 | G11: / | H11: / | I11: / | J11: 61.5 | K11: 62 | L11: 61.8 | M11: / | N11: =AVERAGE(J11:L11) -> 61.766667 | O11: 14.16 | P11: 5.4 | R11: 161 | S11: 91 | T11: 44 | U11: 15
A12: B | B12: AC-20 | C12: 方案一90# | D12: 试件1（浸） | E12: =100*F12/(100-F12) -> 4.2 | F12: 4.0307102 | G12: 1215.8 | H12: 718.3 | I12: 1219 | J12: 64.42 | K12: 64.43 | L12: 64.18 | M12: 64.38 | N12: 64.3525 | O12: 13.36 | P12: 2.26 | Q12: =100*AVERAGE(O12,O14,O16)/AVERAGEA(O13,O15) -> 92.473815 | R12: 161 | S12: 91 | T12: 44 | U12: 15
A13: B | C13: 方案一90# | D13: 试件2 | E13: =100*F13/(100-F13) -> 4.2 | F13: 4.0307102 | G13: 1215.4 | H13: 719.6 | I13: 1218.1 | J13: 63.37 | K13: 63.48 | L13: 63.31 | M13: 63.56 | N13: 63.43 | O13: 15.91 | P13: 2.53 | R13: 161 | S13: 91 | T13: 44 | U13: 15
A14: B | C14: 方案一90# | D14: 试件3（浸） | E14: =100*F14/(100-F14) -> 4.2 | F14: 4.0307102 | G14: 1214.4 | H14: 716.5 | I14: 1217.3 | J14: 63.92 | K14: 64.16 | L14: 64.09 | M14: 64.26 | N14: 64.1075 | O14: 14.77 | P14: 3.01 | R14: 161 | S14: 91 | T14: 44 | U14: 15
A15: B | C15: 方案一90# | D15: 试件4 | E15: =100*F15/(100-F15) -> 4.2 | F15: 4.0307102 | G15: 1215.1 | H15: 719.5 | I15: 1218.7 | J15: 64.44 | K15: 64.16 | L15: 64.39 | M15: 64.36 | N15: 64.3375 | O15: 14.96 | P15: 2.51 | R15: 161 | S15: 91 | T15: 44 | U15: 15
A16: B | C16: 方案一90# | D16: 试件5（浸） | E16: =100*F16/(100-F16) -> 4.2 | F16: 4.0307102 | G16: 1210.9 | H16: 714.5 | I16: 1213.1 | J16: 64.45 | K16: 64.2 | L16: 64.57 | M16: 64.52 | N16: 64.435 | O16: 14.69 | P16: 2.46 | R16: 161 | S16: 91 | T16: 44 | U16: 15
A17: B | C17: 方案二90# | D17: 试件1（浸） | E17: =100*F17/(100-F17) -> 4.2 | F17: 4.0307102 | G17: 1219.2 | H17: 725.4 | I17: 1222.2 | J17: 63.58 | K17: 63.41 | L17: 63.86 | M17: 63.3 | N17: 63.5375 | O17: 14.15 | P17: 3.04 | Q17: =100*AVERAGE(O17,O19,O21)/AVERAGEA(O18,O20) -> 94.282561 | R17: 161 | S17: 91 | T17: 44 | U17: 15
A18: B | C18: 方案二90# | D18: 试件2 | E18: =100*F18/(100-F18) -> 4.2 | F18: 4.0307102 | G18: 1217.2 | H18: 721.2 | I18: 1220.7 | J18: 63.64 | K18: 63.14 | L18: 63.85 | M18: 63.91 | N18: 63.635 | O18: 15.08 | P18: 2.35 | R18: 161 | S18: 91 | T18: 44 | U18: 15
A19: B | C19: 方案二90# | D19: 试件3（浸） | E19: =100*F19/(100-F19) -> 4.2 | F19: 4.0307102 | G19: 1216.8 | H19: 722.5 | I19: 1220.4 | J19: 63.32 | K19: 63.14 | L19: 63.62 | M19: 63.13 | N19: 63.3025 | O19: 14.37 | P19: 3.98 | R19: 161 | S19: 91 | T19: 44 | U19: 15
A20: B | C20: 方案二90# | D20: 试件4 | E20: =100*F20/(100-F20) -> 4.2 | F20: 4.0307102 | G20: 1216.1 | H20: 720.6 | I20: 1219.6 | J20: 63.89 | K20: 63.57 | L20: 64.06 | M20: 63.44 | N20: 63.74 | O20: 15.12 | P20: 2.03 | R20: 161 | S20: 91 | T20: 44 | U20: 15
A21: B | C21: 方案二90# | D21: 试件5（浸） | E21: =100*F21/(100-F21) -> 4.2 | F21: 4.0307102 | G21: 1219.3 | H21: 723.2 | I21: 1222.5 | J21: 63.94 | K21: 63.44 | L21: 63.87 | M21: 63.49 | N21: 63.685 | O21: 14.19 | P21: 3.38 | R21: 161 | S21: 91 | T21: 44 | U21: 15
A22: B | C22: 方案三90# | D22: 试件1（浸） | E22: =100*F22/(100-F22) -> 4.2 | F22: 4.0307102 | G22: 1221.5 | H22: 725.7 | I22: 1224 | J22: 64.33 | K22: 64.76 | L22: 64.41 | M22: 64.11 | N22: =AVERAGE(J22:M22) -> 64.4025 | O22: 14.03 | P22: 3.62 | Q22: =100*AVERAGE(O22,O24,O26)/AVERAGEA(O23,O25) -> 88.341211 | R22: 161 | S22: 91 | T22: 44 | U22: 15
A23: B | C23: 方案三90# | D23: 试件2 | E23: =100*F23/(100-F23) -> 4.2 | F23: 4.0307102 | G23: 1221.1 | H23: 725 | I23: 1223.2 | J23: 64 | K23: 64.51 | L23: 64.12 | M23: 64.5 | N23: =AVERAGE(J23:M23) -> 64.2825 | O23: 15.55 | P23: 3.48 | R23: 161 | S23: 91 | T23: 44 | U23: 15
A24: B | C24: 方案三90# | D24: 试件3（浸） | E24: =100*F24/(100-F24) -> 4.2 | F24: 4.0307102 | G24: 1221.2 | H24: 723.6 | I24: 1223.9 | J24: 63.74 | K24: 63.59 | L24: 63.83 | M24: 63.46 | N24: =AVERAGE(J24:M24) -> 63.655 | O24: 12.72 | P24: 2.65 | R24: 161 | S24: 91 | T24: 44 | U24: 15
A25: B | C25: 方案三90# | D25: 试件4 | E25: =100*F25/(100-F25) -> 4.2 | F25: 4.0307102 | G25: 1220.2 | H25: 721.5 | I25: 1221.7 | J25: 63.59 | K25: 63.47 | L25: 63.65 | M25: 63.47 | N25: =AVERAGE(J25:M25) -> 63.545 | O25: 14.07 | P25: 2.3 | R25: 161 | S25: 91 | T25: 44 | U25: 15
A26: B | C26: 方案三90# | D26: 试件5（浸） | E26: =100*F26/(100-F26) -> 4.2 | F26: 4.0307102 | G26: 1220 | H26: 723.6 | I26: 1223.2 | J26: 63.88 | K26: 63.91 | L26: 64.43 | M26: 63.96 | N26: =AVERAGE(J26:M26) -> 64.045 | O26: 12.5 | P26: 3.28 | R26: 161 | S26: 91 | T26: 44 | U26: 15
A27: B | C27: 方案五90# | D27: 试件1（浸） | E27: =100*F27/(100-F27) -> 4.2 | F27: 4.0307102 | G27: 1218.5 | H27: 721.6 | I27: 1220.7 | J27: 63.74 | K27: 63.92 | L27: 63.93 | M27: 63.86 | N27: =AVERAGE(J27:M27) -> 63.8625 | O27: 13.04 | P27: 3.11 | Q27: =100*AVERAGE(O27,O29,O31)/AVERAGEA(O28,O30) -> 91.539823 | R27: 161 | S27: 91 | T27: 44 | U27: 15
A28: B | C28: 方案五90# | D28: 试件2 | E28: =100*F28/(100-F28) -> 4.2 | F28: 4.0307102 | G28: 1216.9 | H28: 719.1 | I28: 1218.9 | J28: 63.88 | K28: 63.66 | L28: 63.43 | M28: 63.43 | N28: =AVERAGE(J28:M28) -> 63.6 | O28: 14 | P28: 2.41 | R28: 161 | S28: 91 | T28: 44 | U28: 15
A29: B | C29: 方案五90# | D29: 试件3（浸） | E29: =100*F29/(100-F29) -> 4.2 | F29: 4.0307102 | G29: 1214.7 | H29: 717.6 | I29: 1217.2 | J29: 63.94 | K29: 63.97 | L29: 63.72 | M29: 63.7 | N29: =AVERAGE(J29:M29) -> 63.8325 | O29: 12.55 | P29: 3.1 | R29: 161 | S29: 91 | T29: 44 | U29: 15
A30: B | C30: 方案五90# | D30: 试件4 | E30: =100*F30/(100-F30) -> 4.2 | F30: 4.0307102 | G30: 1214.5 | H30: 717.1 | I30: 1217.4 | J30: 63.38 | K30: 63.45 | L30: 63.66 | M30: 63.71 | N30: =AVERAGE(J30:M30) -> 63.55 | O30: 14.25 | P30: 2.25 | R30: 161 | S30: 91 | T30: 44 | U30: 15
A31: B | C31: 方案五90# | D31: 试件5（浸） | E31: =100*F31/(100-F31) -> 4.2 | F31: 4.0307102 | G31: 1214.8 | H31: 717.7 | I31: 1218.5 | J31: 64.93 | K31: 64.72 | L31: 64.62 | M31: 64.61 | N31: =AVERAGE(J31:M31) -> 64.72 | O31: 13.2 | P31: 3.96 | R31: 161 | S31: 91 | T31: 44 | U31: 15
